Workbook

Sheet Cover
B2: Multi-Entity FP&A & Controllership Reporting Suite
B4: Simulated month-end close, budgeting, forecasting, and management reporting package
B6: Source system: Microsoft Dynamics 365 Finance & Operations (simulated exports)
B8: Entities covered | C8: DE01 - Germany GmbH Berlin | DE02 - Germany GmbH Munich | US01 - US Holdings Inc
B9: Reporting currency | C9: USD (EUR entities translated at month-end FX rate)
B10: Period | C10: Jan 2025 - Dec 2025
B12: Tab | C12: Purpose
B13: Data_GL / Data_BS / Data_Budget | C13: Cleaned, validated data pulled from D365 exports (source of all formulas below)
B14: P&L | C14: Monthly P&L by entity + consolidated, fully formula-driven
B15: Balance_Sheet | C15: Monthly balance sheet by entity + consolidated, with balance check
B16: Cash_Flow | C16: Indirect-method cash flow statement derived from P&L and Balance Sheet
B17: Budget_vs_Actual | C17: Monthly variance analysis with commentary flags
B18: Rolling_Forecast | C18: 6-month rolling forecast off trailing trend, adjustable growth assumption
B19: Cost_Center_Drilldown | C19: Spend by cost center with over/under-budget flags for business partnering
B20: Month_End_Close_Checklist | C20: Close task tracker (owner, due date, status) incl. data-quality log from D365 import
... B22: Executive_Dashboard | C22: KPI summary and charts for management presentation

Sheet Executive_Dashboard
B2: Executive Dashboard — Consolidated (All 3 Entities)
B3: FY2025 | Source: Microsoft Dynamics 365 F&O (simulated) | Auto-refreshes from P&L / Balance Sheet / Cost Center tabs
B5: FY Revenue | E5: FY EBITDA | H5: EBITDA Margin | K5: FY Net Income | N5: Dec-25 Cash (Selected Entity, see P&L tab)
B6: ='P&L'!O8 -> 18209098 | E6: ='P&L'!O26 -> 6361165.4 | H6: ='P&L'!O26/'P&L'!O8 -> 0.34933996 | K6: ='P&L'!O32 -> 5812863.5 | N6: =Cash_Flow!M23 -> 2353578.5
B10: Chart Data (hidden helper rows below; formulas reference other tabs)
A11: Month | B11: Jan-25 | C11: Feb-25 | D11: Mar-25 | E11: Apr-25 | F11: May-25 | G11: Jun-25 | H11: Jul-25 | I11: Aug-25 | J11: Sep-25 | K11: Oct-25 | L11: Nov-25 | M11: Dec-25
A12: Revenue | B12: =SUMIFS(Data_GL!$G:$G,Data_GL!$B:$B,"2025-01",Data_GL!$C:$C,"4000")+SUMIFS(Data_GL!$G:$G,Data_GL!$B:$B,"2025-01",Data_GL!$C:$C,"4010") -> 1413032 | C12: =SUMIFS(Data_GL!$G:$G,Data_GL!$B:$B,"2025-02",Data_GL!$C:$C,"4000")+SUMIFS(Data_GL!$G:$G,Data_GL!$B:$B,"2025-02",Data_GL!$C:$C,"4010") -> 1520958.2 | D12: =SUMIFS(Data_GL!$G:$G,Data_GL!$B:$B,"2025-03",Data_GL!$C:$C,"4000")+SUMIFS(Data_GL!$G:$G,Data_GL!$B:$B,"2025-03",Data_GL!$C:$C,"4010") -> 1509294.1 | E12: =SUMIFS(Data_GL!$G:$G,Data_GL!$B:$B,"2025-04",Data_GL!$C:$C,"4000")+SUMIFS(Data_GL!$G:$G,Data_GL!$B:$B,"2025-04",Data_GL!$C:$C,"4010") -> 1552697.4 | F12: =SUMIFS(Data_GL!$G:$G,Data_GL!$B:$B,"2025-05",Data_GL!$C:$C,"4000")+SUMIFS(Data_GL!$G:$G,Data_GL!$B:$B,"2025-05",Data_GL!$C:$C,"4010") -> 1575904.4 | G12: =SUMIFS(Data_GL!$G:$G,Data_GL!$B:$B,"2025-06",Data_GL!$C:$C,"4000")+SUMIFS(Data_GL!$G:$G,Data_GL!$B:$B,"2025-06",Data_GL!$C:$C,"4010") -> 1610969.1 | H12: =SUMIFS(Data_GL!$G:$G,Data_GL!$B:$B,"2025-07",Data_GL!$C:$C,"4000")+SUMIFS(Data_GL!$G:$G,Data_GL!$B:$B,"2025-07",Data_GL!$C:$C,"4010") -> 1561755.7 | I12: =SUMIFS(Data_GL!$G:$G,Data_GL!$B:$B,"2025-08",Data_GL!$C:$C,"4000")+SUMIFS(Data_GL!$G:$G,Data_GL!$B:$B,"2025-08",Data_GL!$C:$C,"4010") -> 1482789.6 | J12: =SUMIFS(Data_GL!$G:$G,Data_GL!$B:$B,"2025-09",Data_GL!$C:$C,"4000")+SUMIFS(Data_GL!$G:$G,Data_GL!$B:$B,"2025-09",Data_GL!$C:$C,"4010") -> 1452931.8 | K12: =SUMIFS(Data_GL!$G:$G,Data_GL!$B:$B,"2025-10",Data_GL!$C:$C,"4000")+SUMIFS(Data_GL!$G:$G,Data_GL!$B:$B,"2025-10",Data_GL!$C:$C,"4010") -> 1452547.4 | L12: =SUMIFS(Data_GL!$G:$G,Data_GL!$B:$B,"2025-11",Data_GL!$C:$C,"4000")+SUMIFS(Data_GL!$G:$G,Data_GL!$B:$B,"2025-11",Data_GL!$C:$C,"4010") -> 1507520.9 | M12: =SUMIFS(Data_GL!$G:$G,Data_GL!$B:$B,"2025-12",Data_GL!$C:$C,"4000")+SUMIFS(Data_GL!$G:$G,Data_GL!$B:$B,"2025-12",Data_GL!$C:$C,"4010") -> 1568697
A13: EBITDA Margin % | B13: =IF(B12=0,0,(B12-(SUMIFS(Data_GL!$G:$G,Data_GL!$B:$B,"2025-01",Data_GL!$C:$C,"5000")+SUMIFS(Data_GL!$G:$G,Data_GL!$B:$B,"2025-01",Data_GL!$C:$C,"5010"))-(SUMIFS(Data_GL!$G:$G,Data_GL!$B:$B,"2025-01",Data_GL!$C:$C,"6000")+SUMIFS(Data_GL!$G:$G,Data_GL!$B:$B,"2025-01",Data_GL!$C:$C,"6010")+SUMIFS(Data_GL!$G:$G,Data_GL!$B:$B,"2025-01",Data_GL!$C:$C,"6020")+SUMIFS(Data_GL!$G:$G,Data_GL!$B:$B,"2025-01",Data_GL!$C:$C,"6030")+SUMIFS(Data_GL!$G:$G,Data_GL!$B:$B,"2025-01",Data_GL!$C:$C,"6040")))/B12) -> 0.35342858 | C13: =IF(C12=0,0,(C12-(SUMIFS(Data_GL!$G:$G,Data_GL!$B:$B,"2025-02",Data_GL!$C:$C,"5000")+SUMIFS(Data_GL!$G:$G,Data_GL!$B:$B,"2025-02",Data_GL!$C:$C,"5010"))-(SUMIFS(Data_GL!$G:$G,Data_GL!$B:$B,"2025-02",Data_GL!$C:$C,"6000")+SUMIFS(Data_GL!$G:$G,Data_GL!$B:$B,"2025-02",Data_GL!$C:$C,"6010")+SUMIFS(Data_GL!$G:$G,Data_GL!$B:$B,"2025-02",Data_GL!$C:$C,"6020")+SUMIFS(Data_GL!$G:$G,Data_GL!$B:$B,"2025-02",Data_GL!$C:$C,"6030")+SUMIFS(Data_GL!$G:$G,Data_GL!$B:$B,"2025-02",Data_GL!$C:$C,"6040")))/C12) -> 0.34997683 | D13: =IF(D12=0,0,(D12-(SUMIFS(Data_GL!$G:$G,Data_GL!$B:$B,"2025-03",Data_GL!$C:$C,"5000")+SUMIFS(Data_GL!$G:$G,Data_GL!$B:$B,"2025-03",Data_GL!$C:$C,"5010"))-(SUMIFS(Data_GL!$G:$G,Data_GL!$B:$B,"2025-03",Data_GL!$C:$C,"6000")+SUMIFS(Data_GL!$G:$G,Data_GL!$B:$B,"2025-03",Data_GL!$C:$C,"6010")+SUMIFS(Data_GL!$G:$G,Data_GL!$B:$B,"2025-03",Data_GL!$C:$C,"6020")+SUMIFS(Data_GL!$G:$G,Data_GL!$B:$B,"2025-03",Data_GL!$C:$C,"6030")+SUMIFS(Data_GL!$G:$G,Data_GL!$B:$B,"2025-03",Data_GL!$C:$C,"6040")))/D12) -> 0.35255412 | E13: =IF(E12=0,0,(E12-(SUMIFS(Data_GL!$G:$G,Data_GL!$B:$B,"2025-04",Data_GL!$C:$C,"5000")+SUMIFS(Data_GL!$G:$G,Data_GL!$B:$B,"2025-04",Data_GL!$C:$C,"5010"))-(SUMIFS(Data_GL!$G:$G,Data_GL!$B:$B,"2025-04",Data_GL!$C:$C,"6000")+SUMIFS(Data_GL!$G:$G,Data_GL!$B:$B,"2025-04",Data_GL!$C:$C,"6010")+SUMIFS(Data_GL!$G:$G,Data_GL!$B:$B,"2025-04",Data_GL!$C:$C,"6020")+SUMIFS(Data_GL!$G:$G,Data_GL!$B:$B,"2025-04",Data_GL!$C:$C,"6030")+SUMIFS(Data_GL!$G:$G,Data_GL!$B:$B,"2025-04",Data_GL!$C:$C,"6040")))/E12) -> 0.34968949 | F13: =IF(F12=0,0,(F12-(SUMIFS(Data_GL!$G:$G,Data_GL!$B:$B,"2025-05",Data_GL!$C:$C,"5000")+SUMIFS(Data_GL!$G:$G,Data_GL!$B:$B,"2025-05",Data_GL!$C:$C,"5010"))-(SUMIFS(Data_GL!$G:$G,Data_GL!$B:$B,"2025-05",Data_GL!$C:$C,"6000")+SUMIFS(Data_GL!$G:$G,Data_GL!$B:$B,"2025-05",Data_GL!$C:$C,"6010")+SUMIFS(Data_GL!$G:$G,Data_GL!$B:$B,"2025-05",Data_GL!$C:$C,"6020")+SUMIFS(Data_GL!$G:$G,Data_GL!$B:$B,"2025-05",Data_GL!$C:$C,"6030")+SUMIFS(Data_GL!$G:$G,Data_GL!$B:$B,"2025-05",Data_GL!$C:$C,"6040")))/F12) -> 0.34675204 | G13: =IF(G12=0,0,(G12-(SUMIFS(Data_GL!$G:$G,Data_GL!$B:$B,"2025-06",Data_GL!$C:$C,"5000")+SUMIFS(Data_GL!$G:$G,Data_GL!$B:$B,"2025-06",Data_GL!$C:$C,"5010"))-(SUMIFS(Data_GL!$G:$G,Data_GL!$B:$B,"2025-06",Data_GL!$C:$C,"6000")+SUMIFS(Data_GL!$G:$G,Data_GL!$B:$B,"2025-06",Data_GL!$C:$C,"6010")+SUMIFS(Data_GL!$G:$G,Data_GL!$B:$B,"2025-06",Data_GL!$C:$C,"6020")+SUMIFS(Data_GL!$G:$G,Data_GL!$B:$B,"2025-06",Data_GL!$C:$C,"6030")+SUMIFS(Data_GL!$G:$G,Data_GL!$B:$B,"2025-06",Data_GL!$C:$C,"6040")))/G12) -> 0.3556789 | H13: =IF(H12=0,0,(H12-(SUMIFS(Data_GL!$G:$G,Data_GL!$B:$B,"2025-07",Data_GL!$C:$C,"5000")+SUMIFS(Data_GL!$G:$G,Data_GL!$B:$B,"2025-07",Data_GL!$C:$C,"5010"))-(SUMIFS(Data_GL!$G:$G,Data_GL!$B:$B,"2025-07",Data_GL!$C:$C,"6000")+SUMIFS(Data_GL!$G:$G,Data_GL!$B:$B,"2025-07",Data_GL!$C:$C,"6010")+SUMIFS(Data_GL!$G:$G,Data_GL!$B:$B,"2025-07",Data_GL!$C:$C,"6020")+SUMIFS(Data_GL!$G:$G,Data_GL!$B:$B,"2025-07",Data_GL!$C:$C,"6030")+SUMIFS(Data_GL!$G:$G,Data_GL!$B:$B,"2025-07",Data_GL!$C:$C,"6040")))/H12) -> 0.34821065 | I13: =IF(I12=0,0,(I12-(SUMIFS(Data_GL!$G:$G,Data_GL!$B:$B,"2025-08",Data_GL!$C:$C,"5000")+SUMIFS(Data_GL!$G:$G,Data_GL!$B:$B,"2025-08",Data_GL!$C:$C,"5010"))-(SUMIFS(Data_GL!$G:$G,Data_GL!$B:$B,"2025-08",Data_GL!$C:$C,"6000")+SUMIFS(Data_GL!$G:$G,Data_GL!$B:$B,"2025-08",Data_GL!$C:$C,"6010")+SUMIFS(Data_GL!$G:$G,Data_GL!$B:$B,"2025-08",Data_GL!$C:$C,"6020")+SUMIFS(Data_GL!$G:$G,Data_GL!$B:$B,"2025-08",Data_GL!$C:$C,"6030")+SUMIFS(Data_GL!$G:$G,Data_GL!$B:$B,"2025-08",Data_GL!$C:$C,"6040")))/I12) -> 0.35102833 | J13: =IF(J12=0,0,(J12-(SUMIFS(Data_GL!$G:$G,Data_GL!$B:$B,"2025-09",Data_GL!$C:$C,"5000")+SUMIFS(Data_GL!$G:$G,Data_GL!$B:$B,"2025-09",Data_GL!$C:$C,"5010"))-(SUMIFS(Data_GL!$G:$G,Data_GL!$B:$B,"2025-09",Data_GL!$C:$C,"6000")+SUMIFS(Data_GL!$G:$G,Data_GL!$B:$B,"2025-09",Data_GL!$C:$C,"6010")+SUMIFS(Data_GL!$G:$G,Data_GL!$B:$B,"2025-09",Data_GL!$C:$C,"6020")+SUMIFS(Data_GL!$G:$G,Data_GL!$B:$B,"2025-09",Data_GL!$C:$C,"6030")+SUMIFS(Data_GL!$G:$G,Data_GL!$B:$B,"2025-09",Data_GL!$C:$C,"6040")))/J12) -> 0.34566828 | K13: =IF(K12=0,0,(K12-(SUMIFS(Data_GL!$G:$G,Data_GL!$B:$B,"2025-10",Data_GL!$C:$C,"5000")+SUMIFS(Data_GL!$G:$G,Data_GL!$B:$B,"2025-10",Data_GL!$C:$C,"5010"))-(SUMIFS(Data_GL!$G:$G,Data_GL!$B:$B,"2025-10",Data_GL!$C:$C,"6000")+SUMIFS(Data_GL!$G:$G,Data_GL!$B:$B,"2025-10",Data_GL!$C:$C,"6010")+SUMIFS(Data_GL!$G:$G,Data_GL!$B:$B,"2025-10",Data_GL!$C:$C,"6020")+SUMIFS(Data_GL!$G:$G,Data_GL!$B:$B,"2025-10",Data_GL!$C:$C,"6030")+SUMIFS(Data_GL!$G:$G,Data_GL!$B:$B,"2025-10",Data_GL!$C:$C,"6040")))/K12) -> 0.34476395 | L13: =IF(L12=0,0,(L12-(SUMIFS(Data_GL!$G:$G,Data_GL!$B:$B,"2025-11",Data_GL!$C:$C,"5000")+SUMIFS(Data_GL!$G:$G,Data_GL!$B:$B,"2025-11",Data_GL!$C:$C,"5010"))-(SUMIFS(Data_GL!$G:$G,Data_GL!$B:$B,"2025-11",Data_GL!$C:$C,"6000")+SUMIFS(Data_GL!$G:$G,Data_GL!$B:$B,"2025-11",Data_GL!$C:$C,"6010")+SUMIFS(Data_GL!$G:$G,Data_GL!$B:$B,"2025-11",Data_GL!$C:$C,"6020")+SUMIFS(Data_GL!$G:$G,Data_GL!$B:$B,"2025-11",Data_GL!$C:$C,"6030")+SUMIFS(Data_GL!$G:$G,Data_GL!$B:$B,"2025-11",Data_GL!$C:$C,"6040")))/L12) -> 0.34319843 | M13: =IF(M12=0,0,(M12-(SUMIFS(Data_GL!$G:$G,Data_GL!$B:$B,"2025-12",Data_GL!$C:$C,"5000")+SUMIFS(Data_GL!$G:$G,Data_GL!$B:$B,"2025-12",Data_GL!$C:$C,"5010"))-(SUMIFS(Data_GL!$G:$G,Data_GL!$B:$B,"2025-12",Data_GL!$C:$C,"6000")+SUMIFS(Data_GL!$G:$G,Data_GL!$B:$B,"2025-12",Data_GL!$C:$C,"6010")+SUMIFS(Data_GL!$G:$G,Data_GL!$B:$B,"2025-12",Data_GL!$C:$C,"6020")+SUMIFS(Data_GL!$G:$G,Data_GL!$B:$B,"2025-12",Data_GL!$C:$C,"6030")+SUMIFS(Data_GL!$G:$G,Data_GL!$B:$B,"2025-12",Data_GL!$C:$C,"6040")))/M12) -> 0.35075956
A15: Bridge Item
A16: FY Actual Revenue | B16: =SUMIFS(Data_GL!$G:$G,Data_GL!$C:$C,"4000")+SUMIFS(Data_GL!$G:$G,Data_GL!$C:$C,"4010") -> 18209098
A17: FY Budget Revenue | B17: =SUMIFS(Data_Budget!$F:$F,Data_Budget!$C:$C,"4000")+SUMIFS(Data_Budget!$F:$F,Data_Budget!$C:$C,"4010") -> 25476861
A19: Cost Center | B19: FY OpEx Spend
A20: Sales & Marketing | B20: =SUMIFS(Data_GL!$G:$G,Data_GL!$F:$F,"CC100",Data_GL!$E:$E,"OpEx") -> 900185.16
A21: Operations | B21: =SUMIFS(Data_GL!$G:$G,Data_GL!$F:$F,"CC200",Data_GL!$E:$E,"OpEx") -> 366210.93
A22: G&A | B22: =SUMIFS(Data_GL!$G:$G,Data_GL!$F:$F,"CC300",Data_GL!$E:$E,"OpEx") -> 3566648.2
A23: R&D / Product | B23: =SUMIFS(Data_GL!$G:$G,Data_GL!$F:$F,"CC400",Data_GL!$E:$E,"OpEx") -> 461641.7
A24: Unallocated | B24: =SUMIFS(Data_GL!$G:$G,Data_GL!$F:$F,"UNALLOCATED",Data_GL!$E:$E,"OpEx") -> 0

Sheet P&L
B2: Select Entity: | C2: DE01 | D2: <- change entity to view; Consolidated column always sums all 3 entities
A4: P&L Line Item | B4: Jan-25 | C4: Feb-25 | D4: Mar-25 | E4: Apr-25 | F4: May-25 | G4: Jun-25 | H4: Jul-25 | I4: Aug-25 | J4: Sep-25 | K4: Oct-25 | L4: Nov-25 | M4: Dec-25 | N4: FY Total (Selected Entity) | O4: FY Total (Consolidated)
A5: Revenue
A6: Product Sales (4000) | B6: =SUMIFS(Data_GL!$G:$G,Data_GL!$A:$A,$C$2,Data_GL!$B:$B,"2025-01",Data_GL!$C:$C,"4000") -> 371697.5 | C6: =SUMIFS(Data_GL!$G:$G,Data_GL!$A:$A,$C$2,Data_GL!$B:$B,"2025-02",Data_GL!$C:$C,"4000") -> 390929.8 | D6: =SUMIFS(Data_GL!$G:$G,Data_GL!$A:$A,$C$2,Data_GL!$B:$B,"2025-03",Data_GL!$C:$C,"4000") -> 383100.69 | E6: =SUMIFS(Data_GL!$G:$G,Data_GL!$A:$A,$C$2,Data_GL!$B:$B,"2025-04",Data_GL!$C:$C,"4000") -> 403134.27 | F6: =SUMIFS(Data_GL!$G:$G,Data_GL!$A:$A,$C$2,Data_GL!$B:$B,"2025-05",Data_GL!$C:$C,"4000") -> 405702.79 | G6: =SUMIFS(Data_GL!$G:$G,Data_GL!$A:$A,$C$2,Data_GL!$B:$B,"2025-06",Data_GL!$C:$C,"4000") -> 401790.83 | H6: =SUMIFS(Data_GL!$G:$G,Data_GL!$A:$A,$C$2,Data_GL!$B:$B,"2025-07",Data_GL!$C:$C,"4000") -> 402323.41 | I6: =SUMIFS(Data_GL!$G:$G,Data_GL!$A:$A,$C$2,Data_GL!$B:$B,"2025-08",Data_GL!$C:$C,"4000") -> 368521.33 | J6: =SUMIFS(Data_GL!$G:$G,Data_GL!$A:$A,$C$2,Data_GL!$B:$B,"2025-09",Data_GL!$C:$C,"4000") -> 368145.89 | K6: =SUMIFS(Data_GL!$G:$G,Data_GL!$A:$A,$C$2,Data_GL!$B:$B,"2025-10",Data_GL!$C:$C,"4000") -> 368257.78 | L6: =SUMIFS(Data_GL!$G:$G,Data_GL!$A:$A,$C$2,Data_GL!$B:$B,"2025-11",Data_GL!$C:$C,"4000") -> 397041.73 | M6: =SUMIFS(Data_GL!$G:$G,Data_GL!$A:$A,$C$2,Data_GL!$B:$B,"2025-12",Data_GL!$C:$C,"4000") -> 406076.36 | N6: =SUM(B6:M6) -> 4666722.4 | O6: =SUMIFS(Data_GL!$G:$G,Data_GL!$C:$C,"4000") -> 12746368
A7: Services (4010) | B7: =SUMIFS(Data_GL!$G:$G,Data_GL!$A:$A,$C$2,Data_GL!$B:$B,"2025-01",Data_GL!$C:$C,"4010") -> 159298.93 | C7: =SUMIFS(Data_GL!$G:$G,Data_GL!$A:$A,$C$2,Data_GL!$B:$B,"2025-02",Data_GL!$C:$C,"4010") -> 167541.34 | D7: =SUMIFS(Data_GL!$G:$G,Data_GL!$A:$A,$C$2,Data_GL!$B:$B,"2025-03",Data_GL!$C:$C,"4010") -> 164186 | E7: =SUMIFS(Data_GL!$G:$G,Data_GL!$A:$A,$C$2,Data_GL!$B:$B,"2025-04",Data_GL!$C:$C,"4010") -> 172771.83 | F7: =SUMIFS(Data_GL!$G:$G,Data_GL!$A:$A,$C$2,Data_GL!$B:$B,"2025-05",Data_GL!$C:$C,"4010") -> 173872.62 | G7: =SUMIFS(Data_GL!$G:$G,Data_GL!$A:$A,$C$2,Data_GL!$B:$B,"2025-06",Data_GL!$C:$C,"4010") -> 172196.07 | H7: =SUMIFS(Data_GL!$G:$G,Data_GL!$A:$A,$C$2,Data_GL!$B:$B,"2025-07",Data_GL!$C:$C,"4010") -> 172424.32 | I7: =SUMIFS(Data_GL!$G:$G,Data_GL!$A:$A,$C$2,Data_GL!$B:$B,"2025-08",Data_GL!$C:$C,"4010") -> 157937.71 | J7: =SUMIFS(Data_GL!$G:$G,Data_GL!$A:$A,$C$2,Data_GL!$B:$B,"2025-09",Data_GL!$C:$C,"4010") -> 157776.81 | K7: =SUMIFS(Data_GL!$G:$G,Data_GL!$A:$A,$C$2,Data_GL!$B:$B,"2025-10",Data_GL!$C:$C,"4010") -> 157824.76 | L7: =SUMIFS(Data_GL!$G:$G,Data_GL!$A:$A,$C$2,Data_GL!$B:$B,"2025-11",Data_GL!$C:$C,"4010") -> 170160.74 | M7: =SUMIFS(Data_GL!$G:$G,Data_GL!$A:$A,$C$2,Data_GL!$B:$B,"2025-12",Data_GL!$C:$C,"4010") -> 174032.73 | N7: =SUM(B7:M7) -> 2000023.9 | O7: =SUMIFS(Data_GL!$G:$G,Data_GL!$C:$C,"4010") -> 5462729.3
A8: Total Revenue | B8: =B6+B7 -> 530996.43 | C8: =C6+C7 -> 558471.14 | D8: =D6+D7 -> 547286.69 | E8: =E6+E7 -> 575906.1 | F8: =F6+F7 -> 579575.41 | G8: =G6+G7 -> 573986.9 | H8: =H6+H7 -> 574747.73 | I8: =I6+I7 -> 526459.04 | ... O8: =O6+O7 -> 18209098
A10: Cost of Goods Sold
A11: Materials (5000) | B11: =SUMIFS(Data_GL!$G:$G,Data_GL!$A:$A,$C$2,Data_GL!$B:$B,"2025-01",Data_GL!$C:$C,"5000") -> 169918.86 | C11: =SUMIFS(Data_GL!$G:$G,Data_GL!$A:$A,$C$2,Data_GL!$B:$B,"2025-02",Data_GL!$C:$C,"5000") -> 178710.76 | D11: =SUMIFS(Data_GL!$G:$G,Data_GL!$A:$A,$C$2,Data_GL!$B:$B,"2025-03",Data_GL!$C:$C,"5000") -> 175131.74 | E11: =SUMIFS(Data_GL!$G:$G,Data_GL!$A:$A,$C$2,Data_GL!$B:$B,"2025-04",Data_GL!$C:$C,"5000") -> 184289.95 | F11: =SUMIFS(Data_GL!$G:$G,Data_GL!$A:$A,$C$2,Data_GL!$B:$B,"2025-05",Data_GL!$C:$C,"5000") -> 185464.13 | G11: =SUMIFS(Data_GL!$G:$G,Data_GL!$A:$A,$C$2,Data_GL!$B:$B,"2025-06",Data_GL!$C:$C,"5000") -> 183675.81 | H11: =SUMIFS(Data_GL!$G:$G,Data_GL!$A:$A,$C$2,Data_GL!$B:$B,"2025-07",Data_GL!$C:$C,"5000") -> 183919.28 | I11: =SUMIFS(Data_GL!$G:$G,Data_GL!$A:$A,$C$2,Data_GL!$B:$B,"2025-08",Data_GL!$C:$C,"5000") -> 168466.89 | J11: =SUMIFS(Data_GL!$G:$G,Data_GL!$A:$A,$C$2,Data_GL!$B:$B,"2025-09",Data_GL!$C:$C,"5000") -> 168295.26 | K11: =SUMIFS(Data_GL!$G:$G,Data_GL!$A:$A,$C$2,Data_GL!$B:$B,"2025-10",Data_GL!$C:$C,"5000") -> 168346.41 | L11: =SUMIFS(Data_GL!$G:$G,Data_GL!$A:$A,$C$2,Data_GL!$B:$B,"2025-11",Data_GL!$C:$C,"5000") -> 181504.8 | M11: =SUMIFS(Data_GL!$G:$G,Data_GL!$A:$A,$C$2,Data_GL!$B:$B,"2025-12",Data_GL!$C:$C,"5000") -> 185634.91 | N11: =SUM(B11:M11) -> 2133358.8 | O11: =SUMIFS(Data_GL!$G:$G,Data_GL!$C:$C,"5000") -> 5826911.2
A12: Freight (5010) | B12: =SUMIFS(Data_GL!$G:$G,Data_GL!$A:$A,$C$2,Data_GL!$B:$B,"2025-01",Data_GL!$C:$C,"5010") -> 31859.78 | C12: =SUMIFS(Data_GL!$G:$G,Data_GL!$A:$A,$C$2,Data_GL!$B:$B,"2025-02",Data_GL!$C:$C,"5010") -> 33508.26 | D12: =SUMIFS(Data_GL!$G:$G,Data_GL!$A:$A,$C$2,Data_GL!$B:$B,"2025-03",Data_GL!$C:$C,"5010") -> 32837.2 | E12: =SUMIFS(Data_GL!$G:$G,Data_GL!$A:$A,$C$2,Data_GL!$B:$B,"2025-04",Data_GL!$C:$C,"5010") -> 34554.37 | F12: =SUMIFS(Data_GL!$G:$G,Data_GL!$A:$A,$C$2,Data_GL!$B:$B,"2025-05",Data_GL!$C:$C,"5010") -> 34774.52 | G12: =SUMIFS(Data_GL!$G:$G,Data_GL!$A:$A,$C$2,Data_GL!$B:$B,"2025-06",Data_GL!$C:$C,"5010") -> 34439.22 | H12: =SUMIFS(Data_GL!$G:$G,Data_GL!$A:$A,$C$2,Data_GL!$B:$B,"2025-07",Data_GL!$C:$C,"5010") -> 34484.86 | I12: =SUMIFS(Data_GL!$G:$G,Data_GL!$A:$A,$C$2,Data_GL!$B:$B,"2025-08",Data_GL!$C:$C,"5010") -> 31587.54 | J12: =SUMIFS(Data_GL!$G:$G,Data_GL!$A:$A,$C$2,Data_GL!$B:$B,"2025-09",Data_GL!$C:$C,"5010") -> 31555.36 | K12: =SUMIFS(Data_GL!$G:$G,Data_GL!$A:$A,$C$2,Data_GL!$B:$B,"2025-10",Data_GL!$C:$C,"5010") -> 31564.95 | L12: =SUMIFS(Data_GL!$G:$G,Data_GL!$A:$A,$C$2,Data_GL!$B:$B,"2025-11",Data_GL!$C:$C,"5010") -> 34032.15 | M12: =SUMIFS(Data_GL!$G:$G,Data_GL!$A:$A,$C$2,Data_GL!$B:$B,"2025-12",Data_GL!$C:$C,"5010") -> 34806.55 | N12: =SUM(B12:M12) -> 400004.76 | O12: =SUMIFS(Data_GL!$G:$G,Data_GL!$C:$C,"5010") -> 1092545.8
A13: Total COGS | B13: =B11+B12 -> 201778.64 | C13: =C11+C12 -> 212219.02 | D13: =D11+D12 -> 207968.94 | E13: =E11+E12 -> 218844.32 | F13: =F11+F12 -> 220238.65 | G13: =G11+G12 -> 218115.03 | H13: =H11+H12 -> 218404.14 | I13: =I11+I12 -> 200054.43 | ... O13: =O11+O12 -> 6919457.1
A15: Gross Profit | B15: =B8-B13 -> 329217.79 | C15: =C8-C13 -> 346252.12 | D15: =D8-D13 -> 339317.75 | E15: =E8-E13 -> 357061.78 | F15: =F8-F13 -> 359336.76 | G15: =G8-G13 -> 355871.87 | H15: =H8-H13 -> 356343.59 | I15: =I8-I13 -> 326404.61 | ... O15: =O8-O13 -> 11289640
A16: Gross Margin % | B16: =IF(B8=0,0,B15/B8) -> 0.62000001 | C16: =IF(C8=0,0,C15/C8) -> 0.62000002 | D16: =IF(D8=0,0,D15/D8) -> 0.62 | E16: =IF(E8=0,0,E15/E8) -> 0.62 | F16: =IF(F8=0,0,F15/F8) -> 0.62000001 | G16: =IF(G8=0,0,G15/G8) -> 0.61999999 | H16: =IF(H8=0,0,H15/H8) -> 0.62 | I16: =IF(I8=0,0,I15/I8) -> 0.62000001 | ... O16: =IF(O8=0,0,O15/O8) -> 0.62
A18: Operating Expenses
A19: Salaries & Wages (6000) | B19: =SUMIFS(Data_GL!$G:$G,Data_GL!$A:$A,$C$2,Data_GL!$B:$B,"2025-01",Data_GL!$C:$C,"6000") -> 84372.08 | C19: =SUMIFS(Data_GL!$G:$G,Data_GL!$A:$A,$C$2,Data_GL!$B:$B,"2025-02",Data_GL!$C:$C,"6000") -> 87257.88 | D19: =SUMIFS(Data_GL!$G:$G,Data_GL!$A:$A,$C$2,Data_GL!$B:$B,"2025-03",Data_GL!$C:$C,"6000") -> 85104.01 | E19: =SUMIFS(Data_GL!$G:$G,Data_GL!$A:$A,$C$2,Data_GL!$B:$B,"2025-04",Data_GL!$C:$C,"6000") -> 92456.1 | F19: =SUMIFS(Data_GL!$G:$G,Data_GL!$A:$A,$C$2,Data_GL!$B:$B,"2025-05",Data_GL!$C:$C,"6000") -> 91379.6 | G19: =SUMIFS(Data_GL!$G:$G,Data_GL!$A:$A,$C$2,Data_GL!$B:$B,"2025-06",Data_GL!$C:$C,"6000") -> 92796.98 | H19: =SUMIFS(Data_GL!$G:$G,Data_GL!$A:$A,$C$2,Data_GL!$B:$B,"2025-07",Data_GL!$C:$C,"6000") -> 90575.17 | I19: =SUMIFS(Data_GL!$G:$G,Data_GL!$A:$A,$C$2,Data_GL!$B:$B,"2025-08",Data_GL!$C:$C,"6000") -> 85598.38 | J19: =SUMIFS(Data_GL!$G:$G,Data_GL!$A:$A,$C$2,Data_GL!$B:$B,"2025-09",Data_GL!$C:$C,"6000") -> 82846.65 | K19: =SUMIFS(Data_GL!$G:$G,Data_GL!$A:$A,$C$2,Data_GL!$B:$B,"2025-10",Data_GL!$C:$C,"6000") -> 87592.85 | L19: =SUMIFS(Data_GL!$G:$G,Data_GL!$A:$A,$C$2,Data_GL!$B:$B,"2025-11",Data_GL!$C:$C,"6000") -> 97731.43 | M19: =SUMIFS(Data_GL!$G:$G,Data_GL!$A:$A,$C$2,Data_GL!$B:$B,"2025-12",Data_GL!$C:$C,"6000") -> 93243.31 | N19: =SUM(B19:M19) -> 1070954.4 | O19: =SUMIFS(Data_GL!$G:$G,Data_GL!$C:$C,"6000") -> 2930240.6
A20: Marketing (6010) | B20: =SUMIFS(Data_GL!$G:$G,Data_GL!$A:$A,$C$2,Data_GL!$B:$B,"2025-01",Data_GL!$C:$C,"6010") -> 27409.62 | C20: =SUMIFS(Data_GL!$G:$G,Data_GL!$A:$A,$C$2,Data_GL!$B:$B,"2025-02",Data_GL!$C:$C,"6010") -> 28681.06 | D20: =SUMIFS(Data_GL!$G:$G,Data_GL!$A:$A,$C$2,Data_GL!$B:$B,"2025-03",Data_GL!$C:$C,"6010") -> 25978.56 | E20: =SUMIFS(Data_GL!$G:$G,Data_GL!$A:$A,$C$2,Data_GL!$B:$B,"2025-04",Data_GL!$C:$C,"6010") -> 26744 | F20: =SUMIFS(Data_GL!$G:$G,Data_GL!$A:$A,$C$2,Data_GL!$B:$B,"2025-05",Data_GL!$C:$C,"6010") -> 28106.94 | G20: =SUMIFS(Data_GL!$G:$G,Data_GL!$A:$A,$C$2,Data_GL!$B:$B,"2025-06",Data_GL!$C:$C,"6010") -> 25887.28 | H20: =SUMIFS(Data_GL!$G:$G,Data_GL!$A:$A,$C$2,Data_GL!$B:$B,"2025-07",Data_GL!$C:$C,"6010") -> 26612.94 | I20: =SUMIFS(Data_GL!$G:$G,Data_GL!$A:$A,$C$2,Data_GL!$B:$B,"2025-08",Data_GL!$C:$C,"6010") -> 25816.13 | J20: =SUMIFS(Data_GL!$G:$G,Data_GL!$A:$A,$C$2,Data_GL!$B:$B,"2025-09",Data_GL!$C:$C,"6010") -> 26731.68 | K20: =SUMIFS(Data_GL!$G:$G,Data_GL!$A:$A,$C$2,Data_GL!$B:$B,"2025-10",Data_GL!$C:$C,"6010") -> 28087.86 | L20: =SUMIFS(Data_GL!$G:$G,Data_GL!$A:$A,$C$2,Data_GL!$B:$B,"2025-11",Data_GL!$C:$C,"6010") -> 28309.33 | M20: =SUMIFS(Data_GL!$G:$G,Data_GL!$A:$A,$C$2,Data_GL!$B:$B,"2025-12",Data_GL!$C:$C,"6010") -> 26122.94 | N20: =SUM(B20:M20) -> 324488.34 | O20: =SUMIFS(Data_GL!$G:$G,Data_GL!$C:$C,"6010") -> 900185.16
A21: IT & Software (6020) | B21: =SUMIFS(Data_GL!$G:$G,Data_GL!$A:$A,$C$2,Data_GL!$B:$B,"2025-01",Data_GL!$C:$C,"6020") -> 14285.81 | C21: =SUMIFS(Data_GL!$G:$G,Data_GL!$A:$A,$C$2,Data_GL!$B:$B,"2025-02",Data_GL!$C:$C,"6020") -> 13638.27 | D21: =SUMIFS(Data_GL!$G:$G,Data_GL!$A:$A,$C$2,Data_GL!$B:$B,"2025-03",Data_GL!$C:$C,"6020") -> 13897.15 | E21: =SUMIFS(Data_GL!$G:$G,Data_GL!$A:$A,$C$2,Data_GL!$B:$B,"2025-04",Data_GL!$C:$C,"6020") -> 14005.77 | F21: =SUMIFS(Data_GL!$G:$G,Data_GL!$A:$A,$C$2,Data_GL!$B:$B,"2025-05",Data_GL!$C:$C,"6020") -> 15831.3 | G21: =SUMIFS(Data_GL!$G:$G,Data_GL!$A:$A,$C$2,Data_GL!$B:$B,"2025-06",Data_GL!$C:$C,"6020") -> 13396.72 | H21: =SUMIFS(Data_GL!$G:$G,Data_GL!$A:$A,$C$2,Data_GL!$B:$B,"2025-07",Data_GL!$C:$C,"6020") -> 13851.53 | I21: =SUMIFS(Data_GL!$G:$G,Data_GL!$A:$A,$C$2,Data_GL!$B:$B,"2025-08",Data_GL!$C:$C,"6020") -> 12716.01 | J21: =SUMIFS(Data_GL!$G:$G,Data_GL!$A:$A,$C$2,Data_GL!$B:$B,"2025-09",Data_GL!$C:$C,"6020") -> 13789.39 | K21: =SUMIFS(Data_GL!$G:$G,Data_GL!$A:$A,$C$2,Data_GL!$B:$B,"2025-10",Data_GL!$C:$C,"6020") -> 13104.71 | L21: =SUMIFS(Data_GL!$G:$G,Data_GL!$A:$A,$C$2,Data_GL!$B:$B,"2025-11",Data_GL!$C:$C,"6020") -> 15289.4 | M21: =SUMIFS(Data_GL!$G:$G,Data_GL!$A:$A,$C$2,Data_GL!$B:$B,"2025-12",Data_GL!$C:$C,"6020") -> 14343.43 | N21: =SUM(B21:M21) -> 168149.49 | O21: =SUMIFS(Data_GL!$G:$G,Data_GL!$C:$C,"6020") -> 461641.7
A22: Facilities & Rent (6030) | B22: =SUMIFS(Data_GL!$G:$G,Data_GL!$A:$A,$C$2,Data_GL!$B:$B,"2025-01",Data_GL!$C:$C,"6030") -> 10495.6 | C22: =SUMIFS(Data_GL!$G:$G,Data_GL!$A:$A,$C$2,Data_GL!$B:$B,"2025-02",Data_GL!$C:$C,"6030") -> 10909.33 | D22: =SUMIFS(Data_GL!$G:$G,Data_GL!$A:$A,$C$2,Data_GL!$B:$B,"2025-03",Data_GL!$C:$C,"6030") -> 10448.78 | E22: =SUMIFS(Data_GL!$G:$G,Data_GL!$A:$A,$C$2,Data_GL!$B:$B,"2025-04",Data_GL!$C:$C,"6030") -> 11582 | F22: =SUMIFS(Data_GL!$G:$G,Data_GL!$A:$A,$C$2,Data_GL!$B:$B,"2025-05",Data_GL!$C:$C,"6030") -> 11583.68 | G22: =SUMIFS(Data_GL!$G:$G,Data_GL!$A:$A,$C$2,Data_GL!$B:$B,"2025-06",Data_GL!$C:$C,"6030") -> 11592.74 | H22: =SUMIFS(Data_GL!$G:$G,Data_GL!$A:$A,$C$2,Data_GL!$B:$B,"2025-07",Data_GL!$C:$C,"6030") -> 11230.2 | I22: =SUMIFS(Data_GL!$G:$G,Data_GL!$A:$A,$C$2,Data_GL!$B:$B,"2025-08",Data_GL!$C:$C,"6030") -> 10851.2 | J22: =SUMIFS(Data_GL!$G:$G,Data_GL!$A:$A,$C$2,Data_GL!$B:$B,"2025-09",Data_GL!$C:$C,"6030") -> 10266.45 | K22: =SUMIFS(Data_GL!$G:$G,Data_GL!$A:$A,$C$2,Data_GL!$B:$B,"2025-10",Data_GL!$C:$C,"6030") -> 11049.59 | L22: =SUMIFS(Data_GL!$G:$G,Data_GL!$A:$A,$C$2,Data_GL!$B:$B,"2025-11",Data_GL!$C:$C,"6030") -> 9858.12 | M22: =SUMIFS(Data_GL!$G:$G,Data_GL!$A:$A,$C$2,Data_GL!$B:$B,"2025-12",Data_GL!$C:$C,"6030") -> 11809.35 | N22: =SUM(B22:M22) -> 131677.04 | O22: =SUMIFS(Data_GL!$G:$G,Data_GL!$C:$C,"6030") -> 361654.69
A23: Professional Fees (6040) | B23: =SUMIFS(Data_GL!$G:$G,Data_GL!$A:$A,$C$2,Data_GL!$B:$B,"2025-01",Data_GL!$C:$C,"6040") -> 7871.7 | C23: =SUMIFS(Data_GL!$G:$G,Data_GL!$A:$A,$C$2,Data_GL!$B:$B,"2025-02",Data_GL!$C:$C,"6040") -> 8478.41 | D23: =SUMIFS(Data_GL!$G:$G,Data_GL!$A:$A,$C$2,Data_GL!$B:$B,"2025-03",Data_GL!$C:$C,"6040") -> 7629.6 | E23: =SUMIFS(Data_GL!$G:$G,Data_GL!$A:$A,$C$2,Data_GL!$B:$B,"2025-04",Data_GL!$C:$C,"6040") -> 8141.45 | F23: =SUMIFS(Data_GL!$G:$G,Data_GL!$A:$A,$C$2,Data_GL!$B:$B,"2025-05",Data_GL!$C:$C,"6040") -> 8233.87 | G23: =SUMIFS(Data_GL!$G:$G,Data_GL!$A:$A,$C$2,Data_GL!$B:$B,"2025-06",Data_GL!$C:$C,"6040") -> 8927.71 | H23: =SUMIFS(Data_GL!$G:$G,Data_GL!$A:$A,$C$2,Data_GL!$B:$B,"2025-07",Data_GL!$C:$C,"6040") -> 9076.9 | I23: =SUMIFS(Data_GL!$G:$G,Data_GL!$A:$A,$C$2,Data_GL!$B:$B,"2025-08",Data_GL!$C:$C,"6040") -> 8303.97 | J23: =SUMIFS(Data_GL!$G:$G,Data_GL!$A:$A,$C$2,Data_GL!$B:$B,"2025-09",Data_GL!$C:$C,"6040") -> 7815.61 | K23: =SUMIFS(Data_GL!$G:$G,Data_GL!$A:$A,$C$2,Data_GL!$B:$B,"2025-10",Data_GL!$C:$C,"6040") -> 8033.92 | L23: =SUMIFS(Data_GL!$G:$G,Data_GL!$A:$A,$C$2,Data_GL!$B:$B,"2025-11",Data_GL!$C:$C,"6040") -> 8857.67 | M23: =SUMIFS(Data_GL!$G:$G,Data_GL!$A:$A,$C$2,Data_GL!$B:$B,"2025-12",Data_GL!$C:$C,"6040") -> 9344.65 | N23: =SUM(B23:M23) -> 100715.46 | O23: =SUMIFS(Data_GL!$G:$G,Data_GL!$C:$C,"6040") -> 274752.88
A24: Total OpEx (before D&A) | B24: =B19+B20+B21+B22+B23 -> 144434.81 | C24: =C19+C20+C21+C22+C23 -> 148964.95 | D24: =D19+D20+D21+D22+D23 -> 143058.1 | E24: =E19+E20+E21+E22+E23 -> 152929.32 | F24: =F19+F20+F21+F22+F23 -> 155135.39 | G24: =G19+G20+G21+G22+G23 -> 152601.43 | H24: =H19+H20+H21+H22+H23 -> 151346.74 | I24: =I19+I20+I21+I22+I23 -> 143285.69 | ... O24: =O19+O20+O21+O22+O23 -> 4928475.1
A26: EBITDA | B26: =B15-B24 -> 184782.98 | C26: =C15-C24 -> 197287.17 | D26: =D15-D24 -> 196259.65 | E26: =E15-E24 -> 204132.46 | F26: =F15-F24 -> 204201.37 | G26: =G15-G24 -> 203270.44 | H26: =H15-H24 -> 204996.85 | I26: =I15-I24 -> 183118.92 | ... O26: =O15-O24 -> 6361165.4
A27: EBITDA Margin % | B27: =IF(B8=0,0,B26/B8) -> 0.34799289 | C27: =IF(C8=0,0,C26/C8) -> 0.35326296 | D27: =IF(D8=0,0,D26/D8) -> 0.35860483 | E27: =IF(E8=0,0,E26/E8) -> 0.35445442 | F27: =IF(F8=0,0,F26/F8) -> 0.35232925 | G27: =IF(G8=0,0,G26/G8) -> 0.35413777 | H27: =IF(H8=0,0,H26/H8) -> 0.35667274 | I27: =IF(I8=0,0,I26/I8) -> 0.34783128 | ... O27: =IF(O8=0,0,O26/O8) -> 0.34933996
A29: Depreciation & Amortization (7000) | B29: =SUMIFS(Data_GL!$G:$G,Data_GL!$A:$A,$C$2,Data_GL!$B:$B,"2025-01",Data_GL!$C:$C,"7000") -> 11458.48 | C29: =SUMIFS(Data_GL!$G:$G,Data_GL!$A:$A,$C$2,Data_GL!$B:$B,"2025-02",Data_GL!$C:$C,"7000") -> 10100.92 | D29: =SUMIFS(Data_GL!$G:$G,Data_GL!$A:$A,$C$2,Data_GL!$B:$B,"2025-03",Data_GL!$C:$C,"7000") -> 11747.87 | E29: =SUMIFS(Data_GL!$G:$G,Data_GL!$A:$A,$C$2,Data_GL!$B:$B,"2025-04",Data_GL!$C:$C,"7000") -> 11734.49 | F29: =SUMIFS(Data_GL!$G:$G,Data_GL!$A:$A,$C$2,Data_GL!$B:$B,"2025-05",Data_GL!$C:$C,"7000") -> 12068.23 | G29: =SUMIFS(Data_GL!$G:$G,Data_GL!$A:$A,$C$2,Data_GL!$B:$B,"2025-06",Data_GL!$C:$C,"7000") -> 11578.1 | H29: =SUMIFS(Data_GL!$G:$G,Data_GL!$A:$A,$C$2,Data_GL!$B:$B,"2025-07",Data_GL!$C:$C,"7000") -> 11692.45 | I29: =SUMIFS(Data_GL!$G:$G,Data_GL!$A:$A,$C$2,Data_GL!$B:$B,"2025-08",Data_GL!$C:$C,"7000") -> 11019.47 | J29: =SUMIFS(Data_GL!$G:$G,Data_GL!$A:$A,$C$2,Data_GL!$B:$B,"2025-09",Data_GL!$C:$C,"7000") -> 9936.61 | K29: =SUMIFS(Data_GL!$G:$G,Data_GL!$A:$A,$C$2,Data_GL!$B:$B,"2025-10",Data_GL!$C:$C,"7000") -> 10182.27 | L29: =SUMIFS(Data_GL!$G:$G,Data_GL!$A:$A,$C$2,Data_GL!$B:$B,"2025-11",Data_GL!$C:$C,"7000") -> 11393.43 | M29: =SUMIFS(Data_GL!$G:$G,Data_GL!$A:$A,$C$2,Data_GL!$B:$B,"2025-12",Data_GL!$C:$C,"7000") -> 11301.53 | N29: =SUM(B29:M29) -> 134213.85 | O29: =SUMIFS(Data_GL!$G:$G,Data_GL!$C:$C,"7000") -> 366210.93
A30: EBIT | B30: =B26-B29 -> 173324.5 | C30: =C26-C29 -> 187186.25 | D30: =D26-D29 -> 184511.78 | E30: =E26-E29 -> 192397.97 | F30: =F26-F29 -> 192133.14 | G30: =G26-G29 -> 191692.34 | H30: =H26-H29 -> 193304.4 | I30: =I26-I29 -> 172099.45 | ... O30: =O26-O29 -> 5994954.5
A31: Interest Expense (8000) | B31: =SUMIFS(Data_GL!$G:$G,Data_GL!$A:$A,$C$2,Data_GL!$B:$B,"2025-01",Data_GL!$C:$C,"8000") -> 5309.97 | C31: =SUMIFS(Data_GL!$G:$G,Data_GL!$A:$A,$C$2,Data_GL!$B:$B,"2025-02",Data_GL!$C:$C,"8000") -> 5584.71 | D31: =SUMIFS(Data_GL!$G:$G,Data_GL!$A:$A,$C$2,Data_GL!$B:$B,"2025-03",Data_GL!$C:$C,"8000") -> 5472.87 | E31: =SUMIFS(Data_GL!$G:$G,Data_GL!$A:$A,$C$2,Data_GL!$B:$B,"2025-04",Data_GL!$C:$C,"8000") -> 5759.06 | F31: =SUMIFS(Data_GL!$G:$G,Data_GL!$A:$A,$C$2,Data_GL!$B:$B,"2025-05",Data_GL!$C:$C,"8000") -> 5795.76 | G31: =SUMIFS(Data_GL!$G:$G,Data_GL!$A:$A,$C$2,Data_GL!$B:$B,"2025-06",Data_GL!$C:$C,"8000") -> 5739.87 | H31: =SUMIFS(Data_GL!$G:$G,Data_GL!$A:$A,$C$2,Data_GL!$B:$B,"2025-07",Data_GL!$C:$C,"8000") -> 5747.48 | I31: =SUMIFS(Data_GL!$G:$G,Data_GL!$A:$A,$C$2,Data_GL!$B:$B,"2025-08",Data_GL!$C:$C,"8000") -> 5264.59 | J31: =SUMIFS(Data_GL!$G:$G,Data_GL!$A:$A,$C$2,Data_GL!$B:$B,"2025-09",Data_GL!$C:$C,"8000") -> 5259.23 | K31: =SUMIFS(Data_GL!$G:$G,Data_GL!$A:$A,$C$2,Data_GL!$B:$B,"2025-10",Data_GL!$C:$C,"8000") -> 5260.83 | L31: =SUMIFS(Data_GL!$G:$G,Data_GL!$A:$A,$C$2,Data_GL!$B:$B,"2025-11",Data_GL!$C:$C,"8000") -> 5672.03 | M31: =SUMIFS(Data_GL!$G:$G,Data_GL!$A:$A,$C$2,Data_GL!$B:$B,"2025-12",Data_GL!$C:$C,"8000") -> 5801.09 | N31: =SUM(B31:M31) -> 66667.49 | O31: =SUMIFS(Data_GL!$G:$G,Data_GL!$C:$C,"8000") -> 182090.99
A32: Net Income | B32: =B30-B31 -> 168014.53 | C32: =C30-C31 -> 181601.54 | D32: =D30-D31 -> 179038.91 | E32: =E30-E31 -> 186638.91 | F32: =F30-F31 -> 186337.38 | G32: =G30-G31 -> 185952.47 | H32: =H30-H31 -> 187556.92 | I32: =I30-I31 -> 166834.86 | ... O32: =O30-O31 -> 5812863.5
A33: Net Margin % | B33: =IF(B8=0,0,B32/B8) -> 0.31641367 | C33: =IF(C8=0,0,C32/C8) -> 0.32517623 | D33: =IF(D8=0,0,D32/D8) -> 0.32713916 | E33: =IF(E8=0,0,E32/E8) -> 0.32407872 | F33: =IF(F8=0,0,F32/F8) -> 0.3215067 | G33: =IF(G8=0,0,G32/G8) -> 0.3239664 | H33: =IF(H8=0,0,H32/H8) -> 0.32632912 | I33: =IF(I8=0,0,I32/I8) -> 0.31689998 | ... O33: =IF(O8=0,0,O32/O8) -> 0.31922853

Sheet Balance_Sheet
B2: Select Entity: | C2: DE01
A4: Balance Sheet Line Item | B4: Jan-25 | C4: Feb-25 | D4: Mar-25 | E4: Apr-25 | F4: May-25 | G4: Jun-25 | H4: Jul-25 | I4: Aug-25 | J4: Sep-25 | K4: Oct-25 | L4: Nov-25 | M4: Dec-25 | N4: Dec-25 (Consolidated)
A5: Assets
A6: Cash & Cash Equivalents | B6: =SUMIFS(Data_BS!$F:$F,Data_BS!$A:$A,$C$2,Data_BS!$B:$B,"2025-01",Data_BS!$C:$C,"1000") -> 431884.01 | C6: =SUMIFS(Data_BS!$F:$F,Data_BS!$A:$A,$C$2,Data_BS!$B:$B,"2025-02",Data_BS!$C:$C,"1000") -> 614216.49 | D6: =SUMIFS(Data_BS!$F:$F,Data_BS!$A:$A,$C$2,Data_BS!$B:$B,"2025-03",Data_BS!$C:$C,"1000") -> 789596.21 | E6: =SUMIFS(Data_BS!$F:$F,Data_BS!$A:$A,$C$2,Data_BS!$B:$B,"2025-04",Data_BS!$C:$C,"1000") -> 963958.75 | F6: =SUMIFS(Data_BS!$F:$F,Data_BS!$A:$A,$C$2,Data_BS!$B:$B,"2025-05",Data_BS!$C:$C,"1000") -> 1146214.6 | G6: =SUMIFS(Data_BS!$F:$F,Data_BS!$A:$A,$C$2,Data_BS!$B:$B,"2025-06",Data_BS!$C:$C,"1000") -> 1332193.6 | H6: =SUMIFS(Data_BS!$F:$F,Data_BS!$A:$A,$C$2,Data_BS!$B:$B,"2025-07",Data_BS!$C:$C,"1000") -> 1509702.8 | I6: =SUMIFS(Data_BS!$F:$F,Data_BS!$A:$A,$C$2,Data_BS!$B:$B,"2025-08",Data_BS!$C:$C,"1000") -> 1671293.6 | J6: =SUMIFS(Data_BS!$F:$F,Data_BS!$A:$A,$C$2,Data_BS!$B:$B,"2025-09",Data_BS!$C:$C,"1000") -> 1835587.3 | K6: =SUMIFS(Data_BS!$F:$F,Data_BS!$A:$A,$C$2,Data_BS!$B:$B,"2025-10",Data_BS!$C:$C,"1000") -> 1997427.3 | L6: =SUMIFS(Data_BS!$F:$F,Data_BS!$A:$A,$C$2,Data_BS!$B:$B,"2025-11",Data_BS!$C:$C,"1000") -> 2163028.2 | M6: =SUMIFS(Data_BS!$F:$F,Data_BS!$A:$A,$C$2,Data_BS!$B:$B,"2025-12",Data_BS!$C:$C,"1000") -> 2353578.5 | N6: =SUMIFS(Data_BS!$F:$F,Data_BS!$B:$B,"2025-12",Data_BS!$C:$C,"1000") -> 6515922.6
A7: Accounts Receivable | B7: =SUMIFS(Data_BS!$F:$F,Data_BS!$A:$A,$C$2,Data_BS!$B:$B,"2025-01",Data_BS!$C:$C,"1200") -> 204566.47 | C7: =SUMIFS(Data_BS!$F:$F,Data_BS!$A:$A,$C$2,Data_BS!$B:$B,"2025-02",Data_BS!$C:$C,"1200") -> 205113.77 | D7: =SUMIFS(Data_BS!$F:$F,Data_BS!$A:$A,$C$2,Data_BS!$B:$B,"2025-03",Data_BS!$C:$C,"1200") -> 208445.22 | E7: =SUMIFS(Data_BS!$F:$F,Data_BS!$A:$A,$C$2,Data_BS!$B:$B,"2025-04",Data_BS!$C:$C,"1200") -> 210266.65 | F7: =SUMIFS(Data_BS!$F:$F,Data_BS!$A:$A,$C$2,Data_BS!$B:$B,"2025-05",Data_BS!$C:$C,"1200") -> 211508.94 | G7: =SUMIFS(Data_BS!$F:$F,Data_BS!$A:$A,$C$2,Data_BS!$B:$B,"2025-06",Data_BS!$C:$C,"1200") -> 209218.52 | H7: =SUMIFS(Data_BS!$F:$F,Data_BS!$A:$A,$C$2,Data_BS!$B:$B,"2025-07",Data_BS!$C:$C,"1200") -> 215542.34 | I7: =SUMIFS(Data_BS!$F:$F,Data_BS!$A:$A,$C$2,Data_BS!$B:$B,"2025-08",Data_BS!$C:$C,"1200") -> 217573.04 | J7: =SUMIFS(Data_BS!$F:$F,Data_BS!$A:$A,$C$2,Data_BS!$B:$B,"2025-09",Data_BS!$C:$C,"1200") -> 220170.22 | K7: =SUMIFS(Data_BS!$F:$F,Data_BS!$A:$A,$C$2,Data_BS!$B:$B,"2025-10",Data_BS!$C:$C,"1200") -> 221014.28 | L7: =SUMIFS(Data_BS!$F:$F,Data_BS!$A:$A,$C$2,Data_BS!$B:$B,"2025-11",Data_BS!$C:$C,"1200") -> 227772.33 | M7: =SUMIFS(Data_BS!$F:$F,Data_BS!$A:$A,$C$2,Data_BS!$B:$B,"2025-12",Data_BS!$C:$C,"1200") -> 223916.06 | N7: =SUMIFS(Data_BS!$F:$F,Data_BS!$B:$B,"2025-12",Data_BS!$C:$C,"1200") -> 683240.56
A8: Fixed Assets, net | B8: =SUMIFS(Data_BS!$F:$F,Data_BS!$A:$A,$C$2,Data_BS!$B:$B,"2025-01",Data_BS!$C:$C,"1500") -> 982145.85 | C8: =SUMIFS(Data_BS!$F:$F,Data_BS!$A:$A,$C$2,Data_BS!$B:$B,"2025-02",Data_BS!$C:$C,"1500") -> 983155.94 | D8: =SUMIFS(Data_BS!$F:$F,Data_BS!$A:$A,$C$2,Data_BS!$B:$B,"2025-03",Data_BS!$C:$C,"1500") -> 984330.73 | E8: =SUMIFS(Data_BS!$F:$F,Data_BS!$A:$A,$C$2,Data_BS!$B:$B,"2025-04",Data_BS!$C:$C,"1500") -> 985504.18 | F8: =SUMIFS(Data_BS!$F:$F,Data_BS!$A:$A,$C$2,Data_BS!$B:$B,"2025-05",Data_BS!$C:$C,"1500") -> 986711 | G8: =SUMIFS(Data_BS!$F:$F,Data_BS!$A:$A,$C$2,Data_BS!$B:$B,"2025-06",Data_BS!$C:$C,"1500") -> 987868.81 | H8: =SUMIFS(Data_BS!$F:$F,Data_BS!$A:$A,$C$2,Data_BS!$B:$B,"2025-07",Data_BS!$C:$C,"1500") -> 989038.05 | I8: =SUMIFS(Data_BS!$F:$F,Data_BS!$A:$A,$C$2,Data_BS!$B:$B,"2025-08",Data_BS!$C:$C,"1500") -> 990140 | J8: =SUMIFS(Data_BS!$F:$F,Data_BS!$A:$A,$C$2,Data_BS!$B:$B,"2025-09",Data_BS!$C:$C,"1500") -> 991133.66 | K8: =SUMIFS(Data_BS!$F:$F,Data_BS!$A:$A,$C$2,Data_BS!$B:$B,"2025-10",Data_BS!$C:$C,"1500") -> 992151.89 | L8: =SUMIFS(Data_BS!$F:$F,Data_BS!$A:$A,$C$2,Data_BS!$B:$B,"2025-11",Data_BS!$C:$C,"1500") -> 993291.23 | M8: =SUMIFS(Data_BS!$F:$F,Data_BS!$A:$A,$C$2,Data_BS!$B:$B,"2025-12",Data_BS!$C:$C,"1500") -> 994421.39 | N8: =SUMIFS(Data_BS!$F:$F,Data_BS!$B:$B,"2025-12",Data_BS!$C:$C,"1500") -> 3048621.1
A9: Total Assets | B9: =B6+B7+B8 -> 1618596.3 | C9: =C6+C7+C8 -> 1802486.2 | D9: =D6+D7+D8 -> 1982372.2 | E9: =E6+E7+E8 -> 2159729.6 | F9: =F6+F7+F8 -> 2344434.6 | G9: =G6+G7+G8 -> 2529280.9 | H9: =H6+H7+H8 -> 2714283.1 | I9: =I6+I7+I8 -> 2879006.7 | ... N9: =N6+N7+N8 -> 10247784
A11: Liabilities
A12: Accounts Payable | B12: =SUMIFS(Data_BS!$F:$F,Data_BS!$A:$A,$C$2,Data_BS!$B:$B,"2025-01",Data_BS!$C:$C,"2000") -> 156681.16 | C12: =SUMIFS(Data_BS!$F:$F,Data_BS!$A:$A,$C$2,Data_BS!$B:$B,"2025-02",Data_BS!$C:$C,"2000") -> 161348.44 | D12: =SUMIFS(Data_BS!$F:$F,Data_BS!$A:$A,$C$2,Data_BS!$B:$B,"2025-03",Data_BS!$C:$C,"2000") -> 164785.03 | E12: =SUMIFS(Data_BS!$F:$F,Data_BS!$A:$A,$C$2,Data_BS!$B:$B,"2025-04",Data_BS!$C:$C,"2000") -> 158181.86 | F12: =SUMIFS(Data_BS!$F:$F,Data_BS!$A:$A,$C$2,Data_BS!$B:$B,"2025-05",Data_BS!$C:$C,"2000") -> 156562.4 | G12: =SUMIFS(Data_BS!$F:$F,Data_BS!$A:$A,$C$2,Data_BS!$B:$B,"2025-06",Data_BS!$C:$C,"2000") -> 156962.29 | H12: =SUMIFS(Data_BS!$F:$F,Data_BS!$A:$A,$C$2,Data_BS!$B:$B,"2025-07",Data_BS!$C:$C,"2000") -> 154872.63 | I12: =SUMIFS(Data_BS!$F:$F,Data_BS!$A:$A,$C$2,Data_BS!$B:$B,"2025-08",Data_BS!$C:$C,"2000") -> 153918.86 | J12: =SUMIFS(Data_BS!$F:$F,Data_BS!$A:$A,$C$2,Data_BS!$B:$B,"2025-09",Data_BS!$C:$C,"2000") -> 153918.32 | K12: =SUMIFS(Data_BS!$F:$F,Data_BS!$A:$A,$C$2,Data_BS!$B:$B,"2025-10",Data_BS!$C:$C,"2000") -> 155702.11 | L12: =SUMIFS(Data_BS!$F:$F,Data_BS!$A:$A,$C$2,Data_BS!$B:$B,"2025-11",Data_BS!$C:$C,"2000") -> 154107.57 | M12: =SUMIFS(Data_BS!$F:$F,Data_BS!$A:$A,$C$2,Data_BS!$B:$B,"2025-12",Data_BS!$C:$C,"2000") -> 155228.11 | N12: =SUMIFS(Data_BS!$F:$F,Data_BS!$B:$B,"2025-12",Data_BS!$C:$C,"2000") -> 489873.65
A13: Accrued Liabilities | B13: =SUMIFS(Data_BS!$F:$F,Data_BS!$A:$A,$C$2,Data_BS!$B:$B,"2025-01",Data_BS!$C:$C,"2100") -> 64380.63 | C13: =SUMIFS(Data_BS!$F:$F,Data_BS!$A:$A,$C$2,Data_BS!$B:$B,"2025-02",Data_BS!$C:$C,"2100") -> 64172.96 | D13: =SUMIFS(Data_BS!$F:$F,Data_BS!$A:$A,$C$2,Data_BS!$B:$B,"2025-03",Data_BS!$C:$C,"2100") -> 63746.03 | E13: =SUMIFS(Data_BS!$F:$F,Data_BS!$A:$A,$C$2,Data_BS!$B:$B,"2025-04",Data_BS!$C:$C,"2100") -> 63221.64 | F13: =SUMIFS(Data_BS!$F:$F,Data_BS!$A:$A,$C$2,Data_BS!$B:$B,"2025-05",Data_BS!$C:$C,"2100") -> 65354.05 | G13: =SUMIFS(Data_BS!$F:$F,Data_BS!$A:$A,$C$2,Data_BS!$B:$B,"2025-06",Data_BS!$C:$C,"2100") -> 65984.79 | H13: =SUMIFS(Data_BS!$F:$F,Data_BS!$A:$A,$C$2,Data_BS!$B:$B,"2025-07",Data_BS!$C:$C,"2100") -> 67647.96 | I13: =SUMIFS(Data_BS!$F:$F,Data_BS!$A:$A,$C$2,Data_BS!$B:$B,"2025-08",Data_BS!$C:$C,"2100") -> 68610.06 | J13: =SUMIFS(Data_BS!$F:$F,Data_BS!$A:$A,$C$2,Data_BS!$B:$B,"2025-09",Data_BS!$C:$C,"2100") -> 69179.86 | K13: =SUMIFS(Data_BS!$F:$F,Data_BS!$A:$A,$C$2,Data_BS!$B:$B,"2025-10",Data_BS!$C:$C,"2100") -> 70341.99 | L13: =SUMIFS(Data_BS!$F:$F,Data_BS!$A:$A,$C$2,Data_BS!$B:$B,"2025-11",Data_BS!$C:$C,"2100") -> 72975.03 | M13: =SUMIFS(Data_BS!$F:$F,Data_BS!$A:$A,$C$2,Data_BS!$B:$B,"2025-12",Data_BS!$C:$C,"2100") -> 74063.34 | N13: =SUMIFS(Data_BS!$F:$F,Data_BS!$B:$B,"2025-12",Data_BS!$C:$C,"2100") -> 227127.69
A14: Long-term Debt | B14: =SUMIFS(Data_BS!$F:$F,Data_BS!$A:$A,$C$2,Data_BS!$B:$B,"2025-01",Data_BS!$C:$C,"2500") -> 542820 | C14: =SUMIFS(Data_BS!$F:$F,Data_BS!$A:$A,$C$2,Data_BS!$B:$B,"2025-02",Data_BS!$C:$C,"2500") -> 540648.72 | D14: =SUMIFS(Data_BS!$F:$F,Data_BS!$A:$A,$C$2,Data_BS!$B:$B,"2025-03",Data_BS!$C:$C,"2500") -> 538486.13 | E14: =SUMIFS(Data_BS!$F:$F,Data_BS!$A:$A,$C$2,Data_BS!$B:$B,"2025-04",Data_BS!$C:$C,"2500") -> 536332.18 | F14: =SUMIFS(Data_BS!$F:$F,Data_BS!$A:$A,$C$2,Data_BS!$B:$B,"2025-05",Data_BS!$C:$C,"2500") -> 534186.85 | G14: =SUMIFS(Data_BS!$F:$F,Data_BS!$A:$A,$C$2,Data_BS!$B:$B,"2025-06",Data_BS!$C:$C,"2500") -> 532050.1 | H14: =SUMIFS(Data_BS!$F:$F,Data_BS!$A:$A,$C$2,Data_BS!$B:$B,"2025-07",Data_BS!$C:$C,"2500") -> 529921.9 | I14: =SUMIFS(Data_BS!$F:$F,Data_BS!$A:$A,$C$2,Data_BS!$B:$B,"2025-08",Data_BS!$C:$C,"2500") -> 527802.22 | J14: =SUMIFS(Data_BS!$F:$F,Data_BS!$A:$A,$C$2,Data_BS!$B:$B,"2025-09",Data_BS!$C:$C,"2500") -> 525691.01 | K14: =SUMIFS(Data_BS!$F:$F,Data_BS!$A:$A,$C$2,Data_BS!$B:$B,"2025-10",Data_BS!$C:$C,"2500") -> 523588.24 | L14: =SUMIFS(Data_BS!$F:$F,Data_BS!$A:$A,$C$2,Data_BS!$B:$B,"2025-11",Data_BS!$C:$C,"2500") -> 521493.89 | M14: =SUMIFS(Data_BS!$F:$F,Data_BS!$A:$A,$C$2,Data_BS!$B:$B,"2025-12",Data_BS!$C:$C,"2500") -> 519407.92 | N14: =SUMIFS(Data_BS!$F:$F,Data_BS!$B:$B,"2025-12",Data_BS!$C:$C,"2500") -> 1572519.4
A15: Total Liabilities | B15: =B12+B13+B14 -> 763881.79 | C15: =C12+C13+C14 -> 766170.12 | D15: =D12+D13+D14 -> 767017.19 | E15: =E12+E13+E14 -> 757735.68 | F15: =F12+F13+F14 -> 756103.3 | G15: =G12+G13+G14 -> 754997.18 | H15: =H12+H13+H14 -> 752442.49 | I15: =I12+I13+I14 -> 750331.14 | ... N15: =N12+N13+N14 -> 2289520.7
A17: Equity
A18: Share Capital | B18: =SUMIFS(Data_BS!$F:$F,Data_BS!$A:$A,$C$2,Data_BS!$B:$B,"2025-01",Data_BS!$C:$C,"3000") -> 436000 | C18: =SUMIFS(Data_BS!$F:$F,Data_BS!$A:$A,$C$2,Data_BS!$B:$B,"2025-02",Data_BS!$C:$C,"3000") -> 436000 | D18: =SUMIFS(Data_BS!$F:$F,Data_BS!$A:$A,$C$2,Data_BS!$B:$B,"2025-03",Data_BS!$C:$C,"3000") -> 436000 | E18: =SUMIFS(Data_BS!$F:$F,Data_BS!$A:$A,$C$2,Data_BS!$B:$B,"2025-04",Data_BS!$C:$C,"3000") -> 436000 | F18: =SUMIFS(Data_BS!$F:$F,Data_BS!$A:$A,$C$2,Data_BS!$B:$B,"2025-05",Data_BS!$C:$C,"3000") -> 436000 | G18: =SUMIFS(Data_BS!$F:$F,Data_BS!$A:$A,$C$2,Data_BS!$B:$B,"2025-06",Data_BS!$C:$C,"3000") -> 436000 | H18: =SUMIFS(Data_BS!$F:$F,Data_BS!$A:$A,$C$2,Data_BS!$B:$B,"2025-07",Data_BS!$C:$C,"3000") -> 436000 | I18: =SUMIFS(Data_BS!$F:$F,Data_BS!$A:$A,$C$2,Data_BS!$B:$B,"2025-08",Data_BS!$C:$C,"3000") -> 436000 | J18: =SUMIFS(Data_BS!$F:$F,Data_BS!$A:$A,$C$2,Data_BS!$B:$B,"2025-09",Data_BS!$C:$C,"3000") -> 436000 | K18: =SUMIFS(Data_BS!$F:$F,Data_BS!$A:$A,$C$2,Data_BS!$B:$B,"2025-10",Data_BS!$C:$C,"3000") -> 436000 | L18: =SUMIFS(Data_BS!$F:$F,Data_BS!$A:$A,$C$2,Data_BS!$B:$B,"2025-11",Data_BS!$C:$C,"3000") -> 436000 | M18: =SUMIFS(Data_BS!$F:$F,Data_BS!$A:$A,$C$2,Data_BS!$B:$B,"2025-12",Data_BS!$C:$C,"3000") -> 436000 | N18: =SUMIFS(Data_BS!$F:$F,Data_BS!$B:$B,"2025-12",Data_BS!$C:$C,"3000") -> 1322000
A19: Retained Earnings | B19: =SUMIFS(Data_BS!$F:$F,Data_BS!$A:$A,$C$2,Data_BS!$B:$B,"2025-01",Data_BS!$C:$C,"3900") -> 418714.53 | C19: =SUMIFS(Data_BS!$F:$F,Data_BS!$A:$A,$C$2,Data_BS!$B:$B,"2025-02",Data_BS!$C:$C,"3900") -> 600316.07 | D19: =SUMIFS(Data_BS!$F:$F,Data_BS!$A:$A,$C$2,Data_BS!$B:$B,"2025-03",Data_BS!$C:$C,"3900") -> 779354.98 | E19: =SUMIFS(Data_BS!$F:$F,Data_BS!$A:$A,$C$2,Data_BS!$B:$B,"2025-04",Data_BS!$C:$C,"3900") -> 965993.89 | F19: =SUMIFS(Data_BS!$F:$F,Data_BS!$A:$A,$C$2,Data_BS!$B:$B,"2025-05",Data_BS!$C:$C,"3900") -> 1152331.3 | G19: =SUMIFS(Data_BS!$F:$F,Data_BS!$A:$A,$C$2,Data_BS!$B:$B,"2025-06",Data_BS!$C:$C,"3900") -> 1338283.7 | H19: =SUMIFS(Data_BS!$F:$F,Data_BS!$A:$A,$C$2,Data_BS!$B:$B,"2025-07",Data_BS!$C:$C,"3900") -> 1525840.7 | I19: =SUMIFS(Data_BS!$F:$F,Data_BS!$A:$A,$C$2,Data_BS!$B:$B,"2025-08",Data_BS!$C:$C,"3900") -> 1692675.5 | J19: =SUMIFS(Data_BS!$F:$F,Data_BS!$A:$A,$C$2,Data_BS!$B:$B,"2025-09",Data_BS!$C:$C,"3900") -> 1862102 | K19: =SUMIFS(Data_BS!$F:$F,Data_BS!$A:$A,$C$2,Data_BS!$B:$B,"2025-10",Data_BS!$C:$C,"3900") -> 2024961.1 | L19: =SUMIFS(Data_BS!$F:$F,Data_BS!$A:$A,$C$2,Data_BS!$B:$B,"2025-11",Data_BS!$C:$C,"3900") -> 2199515.2 | M19: =SUMIFS(Data_BS!$F:$F,Data_BS!$A:$A,$C$2,Data_BS!$B:$B,"2025-12",Data_BS!$C:$C,"3900") -> 2387216.6 | N19: =SUMIFS(Data_BS!$F:$F,Data_BS!$B:$B,"2025-12",Data_BS!$C:$C,"3900") -> 6636263.5
A20: Total Equity | B20: =B18+B19 -> 854714.53 | C20: =C18+C19 -> 1036316.1 | D20: =D18+D19 -> 1215355 | E20: =E18+E19 -> 1401993.9 | F20: =F18+F19 -> 1588331.3 | G20: =G18+G19 -> 1774283.7 | H20: =H18+H19 -> 1961840.7 | I20: =I18+I19 -> 2128675.5 | ... N20: =N18+N19 -> 7958263.5
A22: Total Liabilities + Equity | B22: =B15+B20 -> 1618596.3 | C22: =C15+C20 -> 1802486.2 | D22: =D15+D20 -> 1982372.2 | E22: =E15+E20 -> 2159729.6 | F22: =F15+F20 -> 2344434.6 | G22: =G15+G20 -> 2529280.9 | H22: =H15+H20 -> 2714283.1 | I22: =I15+I20 -> 2879006.7 | ... N22: =N15+N20 -> 10247784
A23: Balance Check (Assets - L&E, should be 0) | B23: =ROUND(B9-B22,0) -> 0 | C23: =ROUND(C9-C22,0) -> 0 | D23: =ROUND(D9-D22,0) -> 0 | E23: =ROUND(E9-E22,0) -> 0 | F23: =ROUND(F9-F22,0) -> 0 | G23: =ROUND(G9-G22,0) -> 0 | H23: =ROUND(H9-H22,0) -> 0 | I23: =ROUND(I9-I22,0) -> 0 | ... N23: =ROUND(N9-N22,0) -> 0

Sheet Cash_Flow
B2: Indirect method | Entity follows the selector on the P&L tab (cell P&L!$C$2)
A4: Cash Flow Line Item | B4: Jan-25 | C4: Feb-25 | D4: Mar-25 | E4: Apr-25 | F4: May-25 | G4: Jun-25 | H4: Jul-25 | I4: Aug-25 | J4: Sep-25 | K4: Oct-25 | L4: Nov-25 | M4: Dec-25
A5: Operating Activities
A6: Net Income (from P&L) | B6: ='P&L'!B32 -> 168014.53 | C6: ='P&L'!C32 -> 181601.54 | D6: ='P&L'!D32 -> 179038.91 | E6: ='P&L'!E32 -> 186638.91 | F6: ='P&L'!F32 -> 186337.38 | G6: ='P&L'!G32 -> 185952.47 | H6: ='P&L'!H32 -> 187556.92 | I6: ='P&L'!I32 -> 166834.86 | ... M6: ='P&L'!M32 -> 187701.33
A7: + Depreciation & Amortization (non-cash) | B7: ='P&L'!B29 -> 11458.48 | C7: ='P&L'!C29 -> 10100.92 | D7: ='P&L'!D29 -> 11747.87 | E7: ='P&L'!E29 -> 11734.49 | F7: ='P&L'!F29 -> 12068.23 | G7: ='P&L'!G29 -> 11578.1 | H7: ='P&L'!H29 -> 11692.45 | I7: ='P&L'!I29 -> 11019.47 | ... M7: ='P&L'!M29 -> 11301.53
A8: (Increase)/Decrease in Accounts Receivable | B8: 0 | C8: =-(Balance_Sheet!C7-Balance_Sheet!B7) -> -547.3 | D8: =-(Balance_Sheet!D7-Balance_Sheet!C7) -> -3331.45 | E8: =-(Balance_Sheet!E7-Balance_Sheet!D7) -> -1821.43 | F8: =-(Balance_Sheet!F7-Balance_Sheet!E7) -> -1242.29 | G8: =-(Balance_Sheet!G7-Balance_Sheet!F7) -> 2290.42 | H8: =-(Balance_Sheet!H7-Balance_Sheet!G7) -> -6323.82 | I8: =-(Balance_Sheet!I7-Balance_Sheet!H7) -> -2030.7 | J8: =-(Balance_Sheet!J7-Balance_Sheet!I7) -> -2597.18 | ... M8: =-(Balance_Sheet!M7-Balance_Sheet!L7) -> 3856.27
A9: Increase/(Decrease) in Accounts Payable | B9: 0 | C9: =Balance_Sheet!C12-Balance_Sheet!B12 -> 4667.28 | D9: =Balance_Sheet!D12-Balance_Sheet!C12 -> 3436.59 | E9: =Balance_Sheet!E12-Balance_Sheet!D12 -> -6603.17 | F9: =Balance_Sheet!F12-Balance_Sheet!E12 -> -1619.46 | G9: =Balance_Sheet!G12-Balance_Sheet!F12 -> 399.89 | H9: =Balance_Sheet!H12-Balance_Sheet!G12 -> -2089.66 | I9: =Balance_Sheet!I12-Balance_Sheet!H12 -> -953.77 | J9: =Balance_Sheet!J12-Balance_Sheet!I12 -> -0.54 | ... M9: =Balance_Sheet!M12-Balance_Sheet!L12 -> 1120.54
A10: Increase/(Decrease) in Accrued Liabilities | B10: 0 | C10: =Balance_Sheet!C13-Balance_Sheet!B13 -> -207.67 | D10: =Balance_Sheet!D13-Balance_Sheet!C13 -> -426.93 | E10: =Balance_Sheet!E13-Balance_Sheet!D13 -> -524.39 | F10: =Balance_Sheet!F13-Balance_Sheet!E13 -> 2132.41 | G10: =Balance_Sheet!G13-Balance_Sheet!F13 -> 630.74 | H10: =Balance_Sheet!H13-Balance_Sheet!G13 -> 1663.17 | I10: =Balance_Sheet!I13-Balance_Sheet!H13 -> 962.1 | J10: =Balance_Sheet!J13-Balance_Sheet!I13 -> 569.8 | ... M10: =Balance_Sheet!M13-Balance_Sheet!L13 -> 1088.31
A11: Cash Flow from Operations | B11: =B6+B7+B8+B9+B10 -> 179473.01 | C11: =C6+C7+C8+C9+C10 -> 195614.77 | D11: =D6+D7+D8+D9+D10 -> 190464.99 | E11: =E6+E7+E8+E9+E10 -> 189424.41 | F11: =F6+F7+F8+F9+F10 -> 197676.27 | G11: =G6+G7+G8+G9+G10 -> 200851.62 | H11: =H6+H7+H8+H9+H10 -> 192499.06 | I11: =I6+I7+I8+I9+I10 -> 175831.96 | ... M11: =M6+M7+M8+M9+M10 -> 205067.98
A13: Investing Activities
A14: Capital Expenditures (proxy: PP&E build) | B14: 0 | C14: =-(Balance_Sheet!C8-Balance_Sheet!B8)-C7 -> -11111.01 | D14: =-(Balance_Sheet!D8-Balance_Sheet!C8)-D7 -> -12922.66 | E14: =-(Balance_Sheet!E8-Balance_Sheet!D8)-E7 -> -12907.94 | F14: =-(Balance_Sheet!F8-Balance_Sheet!E8)-F7 -> -13275.05 | G14: =-(Balance_Sheet!G8-Balance_Sheet!F8)-G7 -> -12735.91 | H14: =-(Balance_Sheet!H8-Balance_Sheet!G8)-H7 -> -12861.69 | I14: =-(Balance_Sheet!I8-Balance_Sheet!H8)-I7 -> -12121.42 | J14: =-(Balance_Sheet!J8-Balance_Sheet!I8)-J7 -> -10930.27 | ... M14: =-(Balance_Sheet!M8-Balance_Sheet!L8)-M7 -> -12431.69
A15: Cash Flow from Investing | B15: =B14 -> 0 | C15: =C14 -> -11111.01 | D15: =D14 -> -12922.66 | E15: =E14 -> -12907.94 | F15: =F14 -> -13275.05 | G15: =G14 -> -12735.91 | H15: =H14 -> -12861.69 | I15: =I14 -> -12121.42 | ... M15: =M14 -> -12431.69
A17: Financing Activities
A18: Debt Issuance/(Repayment) | B18: 0 | C18: =Balance_Sheet!C14-Balance_Sheet!B14 -> -2171.28 | D18: =Balance_Sheet!D14-Balance_Sheet!C14 -> -2162.59 | E18: =Balance_Sheet!E14-Balance_Sheet!D14 -> -2153.95 | F18: =Balance_Sheet!F14-Balance_Sheet!E14 -> -2145.33 | G18: =Balance_Sheet!G14-Balance_Sheet!F14 -> -2136.75 | H18: =Balance_Sheet!H14-Balance_Sheet!G14 -> -2128.2 | I18: =Balance_Sheet!I14-Balance_Sheet!H14 -> -2119.68 | J18: =Balance_Sheet!J14-Balance_Sheet!I14 -> -2111.21 | ... M18: =Balance_Sheet!M14-Balance_Sheet!L14 -> -2085.97
A19: Cash Flow from Financing | B19: =B18 -> 0 | C19: =C18 -> -2171.28 | D19: =D18 -> -2162.59 | E19: =E18 -> -2153.95 | F19: =F18 -> -2145.33 | G19: =G18 -> -2136.75 | H19: =H18 -> -2128.2 | I19: =I18 -> -2119.68 | ... M19: =M18 -> -2085.97
A21: Net Change in Cash | B21: =B11+B15+B19 -> 179473.01 | C21: =C11+C15+C19 -> 182332.48 | D21: =D11+D15+D19 -> 175379.74 | E21: =E11+E15+E19 -> 174362.52 | F21: =F11+F15+F19 -> 182255.89 | G21: =G11+G15+G19 -> 185978.96 | H21: =H11+H15+H19 -> 177509.17 | I21: =I11+I15+I19 -> 161590.86 | ... M21: =M11+M15+M19 -> 190550.32
A22: Beginning Cash Balance | B22: =Balance_Sheet!B6-B21 -> 252411 | C22: =B23 -> 431884.01 | D22: =C23 -> 614216.49 | E22: =D23 -> 789596.23 | F22: =E23 -> 963958.75 | G22: =F23 -> 1146214.6 | H22: =G23 -> 1332193.6 | I22: =H23 -> 1509702.8 | J22: =I23 -> 1671293.6 | ... M22: =L23 -> 2163028.2
A23: Ending Cash Balance (check vs Balance_Sheet) | B23: =B22+B21 -> 431884.01 | C23: =C22+C21 -> 614216.49 | D23: =D22+D21 -> 789596.23 | E23: =E22+E21 -> 963958.75 | F23: =F22+F21 -> 1146214.6 | G23: =G22+G21 -> 1332193.6 | H23: =H22+H21 -> 1509702.8 | I23: =I22+I21 -> 1671293.6 | ... M23: =M22+M21 -> 2353578.5

Sheet Budget_vs_Actual
B2: Select Entity: | C2: DE01
B3: Select Period: | C3: 2025-06
A5: Account | B5: Category | C5: Actual | D5: Budget | E5: Variance $ | F5: Variance % | G5: Commentary Flag
A6: Product Sales (4000) | B6: Revenue | C6: =SUMIFS(Data_GL!$G:$G,Data_GL!$A:$A,$C$2,Data_GL!$B:$B,$C$3,Data_GL!$C:$C,"4000") -> 401790.83 | D6: =SUMIFS(Data_Budget!$F:$F,Data_Budget!$A:$A,$C$2,Data_Budget!$B:$B,$C$3,Data_Budget!$C:$C,"4000") -> 499955.7 | E6: =C6-D6 -> -98164.87 | F6: =IF(D6=0,0,E6/ABS(D6)) -> -0.19634714 | G6: =IF(F6<-0.1,"Investigate - Unfavorable >10%",IF(F6>0.1,"Favorable - review driver","")) -> Investigate - Unfavorable >10%
A7: Services (4010) | B7: Revenue | C7: =SUMIFS(Data_GL!$G:$G,Data_GL!$A:$A,$C$2,Data_GL!$B:$B,$C$3,Data_GL!$C:$C,"4010") -> 172196.07 | D7: =SUMIFS(Data_Budget!$F:$F,Data_Budget!$A:$A,$C$2,Data_Budget!$B:$B,$C$3,Data_Budget!$C:$C,"4010") -> 252924.04 | E7: =C7-D7 -> -80727.97 | F7: =IF(D7=0,0,E7/ABS(D7)) -> -0.31917871 | G7: =IF(F7<-0.1,"Investigate - Unfavorable >10%",IF(F7>0.1,"Favorable - review driver","")) -> Investigate - Unfavorable >10%
A8: Materials (COGS) (5000) | B8: COGS | C8: =SUMIFS(Data_GL!$G:$G,Data_GL!$A:$A,$C$2,Data_GL!$B:$B,$C$3,Data_GL!$C:$C,"5000") -> 183675.81 | D8: =SUMIFS(Data_Budget!$F:$F,Data_Budget!$A:$A,$C$2,Data_Budget!$B:$B,$C$3,Data_Budget!$C:$C,"5000") -> 166061.6 | E8: =D8-C8 -> -17614.21 | F8: =IF(D8=0,0,E8/ABS(D8)) -> -0.10607034 | G8: =IF(F8<-0.1,"Investigate - Unfavorable >10%",IF(F8>0.1,"Favorable - review driver","")) -> Investigate - Unfavorable >10%
A9: Freight (COGS) (5010) | B9: COGS | C9: =SUMIFS(Data_GL!$G:$G,Data_GL!$A:$A,$C$2,Data_GL!$B:$B,$C$3,Data_GL!$C:$C,"5010") -> 34439.22 | D9: =SUMIFS(Data_Budget!$F:$F,Data_Budget!$A:$A,$C$2,Data_Budget!$B:$B,$C$3,Data_Budget!$C:$C,"5010") -> 165986.1 | E9: =D9-C9 -> 131546.88 | F9: =IF(D9=0,0,E9/ABS(D9)) -> 0.79251745 | G9: =IF(F9<-0.1,"Investigate - Unfavorable >10%",IF(F9>0.1,"Favorable - review driver","")) -> Favorable - review driver
A10: Salaries & Wages (6000) | B10: OpEx | C10: =SUMIFS(Data_GL!$G:$G,Data_GL!$A:$A,$C$2,Data_GL!$B:$B,$C$3,Data_GL!$C:$C,"6000") -> 92796.98 | D10: =SUMIFS(Data_Budget!$F:$F,Data_Budget!$A:$A,$C$2,Data_Budget!$B:$B,$C$3,Data_Budget!$C:$C,"6000") -> 36099.48 | E10: =D10-C10 -> -56697.5 | F10: =IF(D10=0,0,E10/ABS(D10)) -> -1.5705905 | G10: =IF(F10<-0.1,"Investigate - Unfavorable >10%",IF(F10>0.1,"Favorable - review driver","")) -> Investigate - Unfavorable >10%
A11: Marketing (6010) | B11: OpEx | C11: =SUMIFS(Data_GL!$G:$G,Data_GL!$A:$A,$C$2,Data_GL!$B:$B,$C$3,Data_GL!$C:$C,"6010") -> 25887.28 | D11: =SUMIFS(Data_Budget!$F:$F,Data_Budget!$A:$A,$C$2,Data_Budget!$B:$B,$C$3,Data_Budget!$C:$C,"6010") -> 36163.52 | E11: =D11-C11 -> 10276.24 | F11: =IF(D11=0,0,E11/ABS(D11)) -> 0.28416039 | G11: =IF(F11<-0.1,"Investigate - Unfavorable >10%",IF(F11>0.1,"Favorable - review driver","")) -> Favorable - review driver
A12: IT & Software (6020) | B12: OpEx | C12: =SUMIFS(Data_GL!$G:$G,Data_GL!$A:$A,$C$2,Data_GL!$B:$B,$C$3,Data_GL!$C:$C,"6020") -> 13396.72 | D12: =SUMIFS(Data_Budget!$F:$F,Data_Budget!$A:$A,$C$2,Data_Budget!$B:$B,$C$3,Data_Budget!$C:$C,"6020") -> 34228.41 | E12: =D12-C12 -> 20831.69 | F12: =IF(D12=0,0,E12/ABS(D12)) -> 0.60860817 | G12: =IF(F12<-0.1,"Investigate - Unfavorable >10%",IF(F12>0.1,"Favorable - review driver","")) -> Favorable - review driver
A13: Facilities & Rent (6030) | B13: OpEx | C13: =SUMIFS(Data_GL!$G:$G,Data_GL!$A:$A,$C$2,Data_GL!$B:$B,$C$3,Data_GL!$C:$C,"6030") -> 11592.74 | D13: =SUMIFS(Data_Budget!$F:$F,Data_Budget!$A:$A,$C$2,Data_Budget!$B:$B,$C$3,Data_Budget!$C:$C,"6030") -> 34454.31 | E13: =D13-C13 -> 22861.57 | F13: =IF(D13=0,0,E13/ABS(D13)) -> 0.66353295 | G13: =IF(F13<-0.1,"Investigate - Unfavorable >10%",IF(F13>0.1,"Favorable - review driver","")) -> Favorable - review driver
A14: Professional Fees (6040) | B14: OpEx | C14: =SUMIFS(Data_GL!$G:$G,Data_GL!$A:$A,$C$2,Data_GL!$B:$B,$C$3,Data_GL!$C:$C,"6040") -> 8927.71 | D14: =SUMIFS(Data_Budget!$F:$F,Data_Budget!$A:$A,$C$2,Data_Budget!$B:$B,$C$3,Data_Budget!$C:$C,"6040") -> 35224.83 | E14: =D14-C14 -> 26297.12 | F14: =IF(D14=0,0,E14/ABS(D14)) -> 0.74655066 | G14: =IF(F14<-0.1,"Investigate - Unfavorable >10%",IF(F14>0.1,"Favorable - review driver","")) -> Favorable - review driver
A15: Total (this view) | C15: =SUM(C6:C14) -> 944703.36 | D15: =SUM(D6:D14) -> 1261098 | E15: =SUM(E6:E14) -> -41391.05

Sheet Rolling_Forecast
B2: Select Entity: | C2: DE01
B3: Monthly Growth Assumption (applied to forecast months): | E3: 0.015 | F3: <- editable assumption (default trailing-3mo avg growth rate)
A5: Revenue Forecast Line | B5: Jan-25 | C5: Feb-25 | D5: Mar-25 | E5: Apr-25 | F5: May-25 | G5: Jun-25 | H5: Jul-25 | I5: Aug-25 | J5: Sep-25 | K5: Oct-25 | L5: Nov-25 | M5: Dec-25 | N5: Jan-26 | O5: Feb-26 | P5: Mar-26 | Q5: Apr-26 | R5: May-26 | S5: Jun-26
A6: Total Revenue (Actual / Forecast) | B6: =SUMIFS(Data_GL!$G:$G,Data_GL!$A:$A,$C$2,Data_GL!$B:$B,"2025-01",Data_GL!$C:$C,"4000")+SUMIFS(Data_GL!$G:$G,Data_GL!$A:$A,$C$2,Data_GL!$B:$B,"2025-01",Data_GL!$C:$C,"4010") -> 530996.43 | C6: =SUMIFS(Data_GL!$G:$G,Data_GL!$A:$A,$C$2,Data_GL!$B:$B,"2025-02",Data_GL!$C:$C,"4000")+SUMIFS(Data_GL!$G:$G,Data_GL!$A:$A,$C$2,Data_GL!$B:$B,"2025-02",Data_GL!$C:$C,"4010") -> 558471.14 | D6: =SUMIFS(Data_GL!$G:$G,Data_GL!$A:$A,$C$2,Data_GL!$B:$B,"2025-03",Data_GL!$C:$C,"4000")+SUMIFS(Data_GL!$G:$G,Data_GL!$A:$A,$C$2,Data_GL!$B:$B,"2025-03",Data_GL!$C:$C,"4010") -> 547286.69 | E6: =SUMIFS(Data_GL!$G:$G,Data_GL!$A:$A,$C$2,Data_GL!$B:$B,"2025-04",Data_GL!$C:$C,"4000")+SUMIFS(Data_GL!$G:$G,Data_GL!$A:$A,$C$2,Data_GL!$B:$B,"2025-04",Data_GL!$C:$C,"4010") -> 575906.1 | F6: =SUMIFS(Data_GL!$G:$G,Data_GL!$A:$A,$C$2,Data_GL!$B:$B,"2025-05",Data_GL!$C:$C,"4000")+SUMIFS(Data_GL!$G:$G,Data_GL!$A:$A,$C$2,Data_GL!$B:$B,"2025-05",Data_GL!$C:$C,"4010") -> 579575.41 | G6: =SUMIFS(Data_GL!$G:$G,Data_GL!$A:$A,$C$2,Data_GL!$B:$B,"2025-06",Data_GL!$C:$C,"4000")+SUMIFS(Data_GL!$G:$G,Data_GL!$A:$A,$C$2,Data_GL!$B:$B,"2025-06",Data_GL!$C:$C,"4010") -> 573986.9 | H6: =SUMIFS(Data_GL!$G:$G,Data_GL!$A:$A,$C$2,Data_GL!$B:$B,"2025-07",Data_GL!$C:$C,"4000")+SUMIFS(Data_GL!$G:$G,Data_GL!$A:$A,$C$2,Data_GL!$B:$B,"2025-07",Data_GL!$C:$C,"4010") -> 574747.73 | I6: =SUMIFS(Data_GL!$G:$G,Data_GL!$A:$A,$C$2,Data_GL!$B:$B,"2025-08",Data_GL!$C:$C,"4000")+SUMIFS(Data_GL!$G:$G,Data_GL!$A:$A,$C$2,Data_GL!$B:$B,"2025-08",Data_GL!$C:$C,"4010") -> 526459.04 | J6: =SUMIFS(Data_GL!$G:$G,Data_GL!$A:$A,$C$2,Data_GL!$B:$B,"2025-09",Data_GL!$C:$C,"4000")+SUMIFS(Data_GL!$G:$G,Data_GL!$A:$A,$C$2,Data_GL!$B:$B,"2025-09",Data_GL!$C:$C,"4010") -> 525922.7 | K6: =SUMIFS(Data_GL!$G:$G,Data_GL!$A:$A,$C$2,Data_GL!$B:$B,"2025-10",Data_GL!$C:$C,"4000")+SUMIFS(Data_GL!$G:$G,Data_GL!$A:$A,$C$2,Data_GL!$B:$B,"2025-10",Data_GL!$C:$C,"4010") -> 526082.54 | L6: =SUMIFS(Data_GL!$G:$G,Data_GL!$A:$A,$C$2,Data_GL!$B:$B,"2025-11",Data_GL!$C:$C,"4000")+SUMIFS(Data_GL!$G:$G,Data_GL!$A:$A,$C$2,Data_GL!$B:$B,"2025-11",Data_GL!$C:$C,"4010") -> 567202.47 | M6: =SUMIFS(Data_GL!$G:$G,Data_GL!$A:$A,$C$2,Data_GL!$B:$B,"2025-12",Data_GL!$C:$C,"4000")+SUMIFS(Data_GL!$G:$G,Data_GL!$A:$A,$C$2,Data_GL!$B:$B,"2025-12",Data_GL!$C:$C,"4010") -> 580109.09 | N6: =M6*(1+$E$3) -> 588810.73 | O6: =N6*(1+$E$3) -> 597642.89 | P6: =O6*(1+$E$3) -> 606607.53 | Q6: =P6*(1+$E$3) -> 615706.64 | R6: =Q6*(1+$E$3) -> 624942.24 | S6: =R6*(1+$E$3) -> 634316.38
A7: Trailing 3-Month Avg Growth Rate | E7: =IF(B6=0,0,(E6-B6)/B6/3) -> 0.028192073 | F7: =IF(C6=0,0,(F6-C6)/C6/3) -> 0.012596455 | G7: =IF(D6=0,0,(G6-D6)/D6/3) -> 0.016262171 | H7: =IF(E6=0,0,(H6-E6)/E6/3) -> -0.00067046231 | I7: =IF(F6=0,0,(I6-F6)/F6/3) -> -0.030549013 | J7: =IF(G6=0,0,(J6-G6)/G6/3) -> -0.027912484 | K7: =IF(H6=0,0,(K6-H6)/H6/3) -> -0.028224087 | L7: =IF(I6=0,0,(L6-I6)/I6/3) -> 0.025797151 | ... S7: =IF(P6=0,0,(S6-P6)/P6/3) -> 0.015226125
A8: Variance vs prior Rolling Forecast (n/a for actuals)

Sheet Cost_Center_Drilldown
B2: Select Entity: | C2: DE01
B3: Select Period: | C3: 2025-06
A5: Cost Center | B5: Actual Spend | C5: Budget (Total OpEx, allocated pro-rata) | D5: % of Total Spend | E5: Variance % | F5: Business Partnering Flag
A6: Sales & Marketing (CC100) | B6: =SUMIFS(Data_GL!$G:$G,Data_GL!$A:$A,$C$2,Data_GL!$B:$B,$C$3,Data_GL!$F:$F,"CC100",Data_GL!$E:$E,"OpEx") -> 25887.28 | C6: =IF($B$11=0,0,B6/$B$11)*(SUMIFS(Data_Budget!$F:$F,Data_Budget!$A:$A,$C$2,Data_Budget!$B:$B,$C$3,Data_Budget!$E:$E,"OpEx")) -> 33479.932 | D6: =IF($B$11=0,0,B6/$B$11) -> 0.15767666 | E6: =IF(C6=0,0,(B6-C6)/C6) -> -0.22678217 | F6: =IF(E6>0.15,"Over budget - discuss with cost center owner",IF(E6<-0.15,"Under-spending - confirm on track","")) -> Under-spending - confirm on track
A7: Operations (CC200) | B7: =SUMIFS(Data_GL!$G:$G,Data_GL!$A:$A,$C$2,Data_GL!$B:$B,$C$3,Data_GL!$F:$F,"CC200",Data_GL!$E:$E,"OpEx") -> 11578.1 | C7: =IF($B$11=0,0,B7/$B$11)*(SUMIFS(Data_Budget!$F:$F,Data_Budget!$A:$A,$C$2,Data_Budget!$B:$B,$C$3,Data_Budget!$E:$E,"OpEx")) -> 14973.918 | D7: =IF($B$11=0,0,B7/$B$11) -> 0.070520972 | E7: =IF(C7=0,0,(B7-C7)/C7) -> -0.22678217 | F7: =IF(E7>0.15,"Over budget - discuss with cost center owner",IF(E7<-0.15,"Under-spending - confirm on track","")) -> Under-spending - confirm on track
A8: G&A (CC300) | B8: =SUMIFS(Data_GL!$G:$G,Data_GL!$A:$A,$C$2,Data_GL!$B:$B,$C$3,Data_GL!$F:$F,"CC300",Data_GL!$E:$E,"OpEx") -> 113317.43 | C8: =IF($B$11=0,0,B8/$B$11)*(SUMIFS(Data_Budget!$F:$F,Data_Budget!$A:$A,$C$2,Data_Budget!$B:$B,$C$3,Data_Budget!$E:$E,"OpEx")) -> 146553.05 | D8: =IF($B$11=0,0,B8/$B$11) -> 0.69020438 | E8: =IF(C8=0,0,(B8-C8)/C8) -> -0.22678217 | F8: =IF(E8>0.15,"Over budget - discuss with cost center owner",IF(E8<-0.15,"Under-spending - confirm on track","")) -> Under-spending - confirm on track
A9: R&D / Product (CC400) | B9: =SUMIFS(Data_GL!$G:$G,Data_GL!$A:$A,$C$2,Data_GL!$B:$B,$C$3,Data_GL!$F:$F,"CC400",Data_GL!$E:$E,"OpEx") -> 13396.72 | C9: =IF($B$11=0,0,B9/$B$11)*(SUMIFS(Data_Budget!$F:$F,Data_Budget!$A:$A,$C$2,Data_Budget!$B:$B,$C$3,Data_Budget!$E:$E,"OpEx")) -> 17325.933 | D9: =IF($B$11=0,0,B9/$B$11) -> 0.081597992 | E9: =IF(C9=0,0,(B9-C9)/C9) -> -0.22678217 | F9: =IF(E9>0.15,"Over budget - discuss with cost center owner",IF(E9<-0.15,"Under-spending - confirm on track","")) -> Under-spending - confirm on track
A10: Unallocated / Needs Review (UNALLOCATED) | B10: =SUMIFS(Data_GL!$G:$G,Data_GL!$A:$A,$C$2,Data_GL!$B:$B,$C$3,Data_GL!$F:$F,"UNALLOCATED",Data_GL!$E:$E,"OpEx") -> 0 | C10: =IF($B$11=0,0,B10/$B$11)*(SUMIFS(Data_Budget!$F:$F,Data_Budget!$A:$A,$C$2,Data_Budget!$B:$B,$C$3,Data_Budget!$E:$E,"OpEx")) -> 0 | D10: =IF($B$11=0,0,B10/$B$11) -> 0 | E10: =IF(C10=0,0,(B10-C10)/C10) -> 0 | F10: =IF(E10>0.15,"Over budget - discuss with cost center owner",IF(E10<-0.15,"Under-spending - confirm on track",""))
A11: Total OpEx Spend | B11: =SUM(B6:B10) -> 164179.53

Sheet Month_End_Close_Checklist
B2: Month-End Close Checklist
B3: Coordinated with Shared Services; owners below are illustrative roles, not names.
B5: Task | C5: Owner | D5: Due (Business Day) | E5: Status | F5: Notes
B6: Lock prior period in D365 GL | C6: Controller | D6: BD1 | E6: Complete | F6: Prevents backdated postings
B7: Pull GL trial balance export from D365 F&O | C7: FP&A Analyst | D7: BD1 | E7: Complete | F7: Source: General ledger > Trial balance
B8: Validate D365 export (duplicates, blank dimensions, FX) | C8: FP&A Analyst | D8: BD2 | E8: Complete | F8: See Data_Quality_Log tab below
B9: Confirm accruals with Shared Services (AP/AR) | C9: Shared Services Lead | D9: BD2 | E9: In Progress | F9: Awaiting confirmation from 1 of 3 entities
